Workbook

Sheet Sièges
A1: MODÈLE VIVANT QC127 – v7.0 · RÉFÉRENCE TRANSPOSÉE + AGRÉGAT DE SONDAGES
A2: Agrégat de 11 rapports de sondage au 31 août 2026 | Référence 2022 transposée sur la carte de 127 circonscriptions (poids électoraux par section de vote) | Seuil de majorité : 64 sièges
A4: Scénario | B4: CAQ | C4: PLQ | D4: QS | E4: PQ | F4: PCQ | G4: Autre | H4: Majorité?
A5: Référence 2022 transposée | B5: =COUNTIF(Modèle!$C$2:$C$128,"CAQ") | C5: =COUNTIF(Modèle!$C$2:$C$128,"PLQ") | D5: =COUNTIF(Modèle!$C$2:$C$128,"QS") | E5: =COUNTIF(Modèle!$C$2:$C$128,"PQ") | F5: =COUNTIF(Modèle!$C$2:$C$128,"PCQ") | G5: =COUNTIF(Modèle!$C$2:$C$128,"Autre") | H5: =IF(MAX(B5:G5)>=64,"OUI ✓","non")
A6: Scén. A – Swing proportionnel | B6: =COUNTIF(Modèle!$AU$2:$AU$128,"CAQ") | C6: =COUNTIF(Modèle!$AU$2:$AU$128,"PLQ") | D6: =COUNTIF(Modèle!$AU$2:$AU$128,"QS") | E6: =COUNTIF(Modèle!$AU$2:$AU$128,"PQ") | F6: =COUNTIF(Modèle!$AU$2:$AU$128,"PCQ") | G6: =COUNTIF(Modèle!$AU$2:$AU$128,"Autre") | H6: =IF(MAX(B6:G6)>=64,"OUI ✓","non")
A7: Scén. B – A + inertie locale | B7: =COUNTIF(Modèle!$AV$2:$AV$128,"CAQ") | C7: =COUNTIF(Modèle!$AV$2:$AV$128,"PLQ") | D7: =COUNTIF(Modèle!$AV$2:$AV$128,"QS") | E7: =COUNTIF(Modèle!$AV$2:$AV$128,"PQ") | F7: =COUNTIF(Modèle!$AV$2:$AV$128,"PCQ") | G7: =COUNTIF(Modèle!$AV$2:$AV$128,"Autre") | H7: =IF(MAX(B7:G7)>=64,"OUI ✓","non")
A8: Scén. C – Fourchette haute (+N2) | B8: =COUNTIF(Modèle!$AW$2:$AW$128,"CAQ") | C8: =COUNTIF(Modèle!$AW$2:$AW$128,"PLQ") | D8: =COUNTIF(Modèle!$AW$2:$AW$128,"QS") | E8: =COUNTIF(Modèle!$AW$2:$AW$128,"PQ") | F8: =COUNTIF(Modèle!$AW$2:$AW$128,"PCQ") | G8: =COUNTIF(Modèle!$AW$2:$AW$128,"Autre") | H8: =IF(MAX(B8:G8)>=64,"OUI ✓","non")
A9: Scén. D – Fourchette basse (–N2) | B9: =COUNTIF(Modèle!$AX$2:$AX$128,"CAQ") | C9: =COUNTIF(Modèle!$AX$2:$AX$128,"PLQ") | D9: =COUNTIF(Modèle!$AX$2:$AX$128,"QS") | E9: =COUNTIF(Modèle!$AX$2:$AX$128,"PQ") | F9: =COUNTIF(Modèle!$AX$2:$AX$128,"PCQ") | G9: =COUNTIF(Modèle!$AX$2:$AX$128,"Autre") | H9: =IF(MAX(B9:G9)>=64,"OUI ✓","non")
A10: Scén. E – Amorti prop./uniforme (Q2) | B10: =COUNTIF(Modèle!$AY$2:$AY$128,"CAQ") | C10: =COUNTIF(Modèle!$AY$2:$AY$128,"PLQ") | D10: =COUNTIF(Modèle!$AY$2:$AY$128,"QS") | E10: =COUNTIF(Modèle!$AY$2:$AY$128,"PQ") | F10: =COUNTIF(Modèle!$AY$2:$AY$128,"PCQ") | G10: =COUNTIF(Modèle!$AY$2:$AY$128,"Autre") | H10: =IF(MAX(B10:G10)>=64,"OUI ✓","non")
A12: Fourchette min (C vs D) | B12: =MIN(B8,B9) | C12: =MIN(C8,C9) | D12: =MIN(D8,D9) | E12: =MIN(E8,E9) | F12: =MIN(F8,F9) | G12: =MIN(G8,G9)
A13: Fourchette max (C vs D) | B13: =MAX(B8,B9) | C13: =MAX(C8,C9) | D13: =MAX(D8,D9) | E13: =MAX(E8,E9) | F13: =MAX(F8,F9) | G13: =MAX(G8,G9)
A15: Circonscriptions serrées à la référence (< 5 pp) : | B15: =COUNTIF(Modèle!$BA$2:$BA$128,"Oui")
A17: Total sièges (contrôle : doit valoir 127) | B17: =SUM(B6:G6) | C17: =SUM(B7:G7) | D17: =SUM(B10:G10)
A19: INTRANTS : onglet Sondages (une ligne par sondage × région, cellules bleues). L'onglet Agrégat calcule le niveau national par régression linéaire pondérée et les décalages régionaux, puis alimente Régions!H2:M6. Paramètres : Régions!N2 (marge), O2 (inertie), Q2 (poids du swing proportionnel).
A20: AVERTISSEMENT : la relation intentions-sièges est fortement non linéaire dans le régime actuel. Un écart de deux points déplace des dizaines de sièges. Ne jamais publier un décompte tiré d'un sondage unique.

Sheet Sondages
A1: SÉRIE DES SONDAGES — une ligne par sondage × région. Cellules bleues = à saisir.
A3: Date (fin terrain) | B3: Firme | C3: Région | D3: n | E3: CAQ | F3: PLQ | G3: QS | H3: PQ | I3: PCQ | J3: Autre | K3: Clé | L3: Nat. | M3: t (jours) | N3: Δ CAQ | O3: Δ PLQ | P3: Δ QS | Q3: Δ PQ | R3: Δ PCQ | S3: Δ Autre | T3: Poids
A4: 2026-05-17 | B4: leger | C4: PROVINCE | D4: 300 | E4: 22 | F4: 28 | G4: 8 | H4: 30 | I4: 11 | J4: 1 | K4: =A4&"|"&B4 | L4: =IF(AND(C4="PROVINCE",B4<>"leger-cumul"),1,0) | M4: =DATEDIF(DATE(LEFT(A4,4),MID(A4,6,2),RIGHT(A4,2)),DATE(LEFT(Agrégat!$B$2,4),MID(Agrégat!$B$2,6,2),RIGHT(Agrégat!$B$2,2)),"d")*-1 | N4: =IFERROR(E4-SUMIFS(E$4:E$58,$K$4:$K$58,$K4,$C$4:$C$58,"PROVINCE"),0) | O4: =IFERROR(F4-SUMIFS(F$4:F$58,$K$4:$K$58,$K4,$C$4:$C$58,"PROVINCE"),0) | P4: =IFERROR(G4-SUMIFS(G$4:G$58,$K$4:$K$58,$K4,$C$4:$C$58,"PROVINCE"),0) | Q4: =IFERROR(H4-SUMIFS(H$4:H$58,$K$4:$K$58,$K4,$C$4:$C$58,"PROVINCE"),0) | R4: =IFERROR(I4-SUMIFS(I$4:I$58,$K$4:$K$58,$K4,$C$4:$C$58,"PROVINCE"),0) | S4: =IFERROR(J4-SUMIFS(J$4:J$58,$K$4:$K$58,$K4,$C$4:$C$58,"PROVINCE"),0) | T4: =IF(C4="PROVINCE",0,0.5^(-M4/Agrégat!$B$4)*SQRT(D4))
A5: 2026-05-17 | B5: leger | C5: Montréal RMR | D5: 300 | E5: 19 | F5: 36 | G5: 10 | H5: 24 | I5: 11 | J5: 0 | K5: =A5&"|"&B5 | L5: =IF(AND(C5="PROVINCE",B5<>"leger-cumul"),1,0) | M5: =DATEDIF(DATE(LEFT(A5,4),MID(A5,6,2),RIGHT(A5,2)),DATE(LEFT(Agrégat!$B$2,4),MID(Agrégat!$B$2,6,2),RIGHT(Agrégat!$B$2,2)),"d")*-1 | N5: =IFERROR(E5-SUMIFS(E$4:E$58,$K$4:$K$58,$K5,$C$4:$C$58,"PROVINCE"),0) | O5: =IFERROR(F5-SUMIFS(F$4:F$58,$K$4:$K$58,$K5,$C$4:$C$58,"PROVINCE"),0) | P5: =IFERROR(G5-SUMIFS(G$4:G$58,$K$4:$K$58,$K5,$C$4:$C$58,"PROVINCE"),0) | Q5: =IFERROR(H5-SUMIFS(H$4:H$58,$K$4:$K$58,$K5,$C$4:$C$58,"PROVINCE"),0) | R5: =IFERROR(I5-SUMIFS(I$4:I$58,$K$4:$K$58,$K5,$C$4:$C$58,"PROVINCE"),0) | S5: =IFERROR(J5-SUMIFS(J$4:J$58,$K$4:$K$58,$K5,$C$4:$C$58,"PROVINCE"),0) | T5: =IF(C5="PROVINCE",0,0.5^(-M5/Agrégat!$B$4)*SQRT(D5))
A6: 2026-05-17 | B6: leger | C6: Québec RMR | D6: 300 | E6: 21.8 | F6: 16.8 | G6: 7.9 | H6: 28.7 | I6: 21.8 | J6: 3 | K6: =A6&"|"&B6 | L6: =IF(AND(C6="PROVINCE",B6<>"leger-cumul"),1,0) | M6: =DATEDIF(DATE(LEFT(A6,4),MID(A6,6,2),RIGHT(A6,2)),DATE(LEFT(Agrégat!$B$2,4),MID(Agrégat!$B$2,6,2),RIGHT(Agrégat!$B$2,2)),"d")*-1 | N6: =IFERROR(E6-SUMIFS(E$4:E$58,$K$4:$K$58,$K6,$C$4:$C$58,"PROVINCE"),0) | O6: =IFERROR(F6-SUMIFS(F$4:F$58,$K$4:$K$58,$K6,$C$4:$C$58,"PROVINCE"),0) | P6: =IFERROR(G6-SUMIFS(G$4:G$58,$K$4:$K$58,$K6,$C$4:$C$58,"PROVINCE"),0) | Q6: =IFERROR(H6-SUMIFS(H$4:H$58,$K$4:$K$58,$K6,$C$4:$C$58,"PROVINCE"),0) | R6: =IFERROR(I6-SUMIFS(I$4:I$58,$K$4:$K$58,$K6,$C$4:$C$58,"PROVINCE"),0) | S6: =IFERROR(J6-SUMIFS(J$4:J$58,$K$4:$K$58,$K6,$C$4:$C$58,"PROVINCE"),0) | T6: =IF(C6="PROVINCE",0,0.5^(-M6/Agrégat!$B$4)*SQRT(D6))
A7: 2026-05-17 | B7: leger | C7: Reste du Québec | D7: 300 | E7: 25 | F7: 21 | G7: 7 | H7: 38 | I7: 8 | J7: 1 | K7: =A7&"|"&B7 | L7: =IF(AND(C7="PROVINCE",B7<>"leger-cumul"),1,0) | M7: =DATEDIF(DATE(LEFT(A7,4),MID(A7,6,2),RIGHT(A7,2)),DATE(LEFT(Agrégat!$B$2,4),MID(Agrégat!$B$2,6,2),RIGHT(Agrégat!$B$2,2)),"d")*-1 | N7: =IFERROR(E7-SUMIFS(E$4:E$58,$K$4:$K$58,$K7,$C$4:$C$58,"PROVINCE"),0) | O7: =IFERROR(F7-SUMIFS(F$4:F$58,$K$4:$K$58,$K7,$C$4:$C$58,"PROVINCE"),0) | P7: =IFERROR(G7-SUMIFS(G$4:G$58,$K$4:$K$58,$K7,$C$4:$C$58,"PROVINCE"),0) | Q7: =IFERROR(H7-SUMIFS(H$4:H$58,$K$4:$K$58,$K7,$C$4:$C$58,"PROVINCE"),0) | R7: =IFERROR(I7-SUMIFS(I$4:I$58,$K$4:$K$58,$K7,$C$4:$C$58,"PROVINCE"),0) | S7: =IFERROR(J7-SUMIFS(J$4:J$58,$K$4:$K$58,$K7,$C$4:$C$58,"PROVINCE"),0) | T7: =IF(C7="PROVINCE",0,0.5^(-M7/Agrégat!$B$4)*SQRT(D7))
A8: 2026-06-07 | B8: synopsis | C8: PROVINCE | D8: 300 | E8: 20.5 | F8: 24.1 | G8: 10.8 | H8: 31.3 | I8: 12 | J8: 1.2 | K8: =A8&"|"&B8 | L8: =IF(AND(C8="PROVINCE",B8<>"leger-cumul"),1,0) | M8: =DATEDIF(DATE(LEFT(A8,4),MID(A8,6,2),RIGHT(A8,2)),DATE(LEFT(Agrégat!$B$2,4),MID(Agrégat!$B$2,6,2),RIGHT(Agrégat!$B$2,2)),"d")*-1 | N8: =IFERROR(E8-SUMIFS(E$4:E$58,$K$4:$K$58,$K8,$C$4:$C$58,"PROVINCE"),0) | O8: =IFERROR(F8-SUMIFS(F$4:F$58,$K$4:$K$58,$K8,$C$4:$C$58,"PROVINCE"),0) | P8: =IFERROR(G8-SUMIFS(G$4:G$58,$K$4:$K$58,$K8,$C$4:$C$58,"PROVINCE"),0) | Q8: =IFERROR(H8-SUMIFS(H$4:H$58,$K$4:$K$58,$K8,$C$4:$C$58,"PROVINCE"),0) | R8: =IFERROR(I8-SUMIFS(I$4:I$58,$K$4:$K$58,$K8,$C$4:$C$58,"PROVINCE"),0) | S8: =IFERROR(J8-SUMIFS(J$4:J$58,$K$4:$K$58,$K8,$C$4:$C$58,"PROVINCE"),0) | T8: =IF(C8="PROVINCE",0,0.5^(-M8/Agrégat!$B$4)*SQRT(D8))
A9: 2026-06-07 | B9: synopsis | C9: Île de Montréal | D9: 300 | E9: 17.1 | F9: 41.5 | G9: 11 | H9: 17.1 | I9: 13.4 | J9: 0 | K9: =A9&"|"&B9 | L9: =IF(AND(C9="PROVINCE",B9<>"leger-cumul"),1,0) | M9: =DATEDIF(DATE(LEFT(A9,4),MID(A9,6,2),RIGHT(A9,2)),DATE(LEFT(Agrégat!$B$2,4),MID(Agrégat!$B$2,6,2),RIGHT(Agrégat!$B$2,2)),"d")*-1 | N9: =IFERROR(E9-SUMIFS(E$4:E$58,$K$4:$K$58,$K9,$C$4:$C$58,"PROVINCE"),0) | O9: =IFERROR(F9-SUMIFS(F$4:F$58,$K$4:$K$58,$K9,$C$4:$C$58,"PROVINCE"),0) | P9: =IFERROR(G9-SUMIFS(G$4:G$58,$K$4:$K$58,$K9,$C$4:$C$58,"PROVINCE"),0) | Q9: =IFERROR(H9-SUMIFS(H$4:H$58,$K$4:$K$58,$K9,$C$4:$C$58,"PROVINCE"),0) | R9: =IFERROR(I9-SUMIFS(I$4:I$58,$K$4:$K$58,$K9,$C$4:$C$58,"PROVINCE"),0) | S9: =IFERROR(J9-SUMIFS(J$4:J$58,$K$4:$K$58,$K9,$C$4:$C$58,"PROVINCE"),0) | T9: =IF(C9="PROVINCE",0,0.5^(-M9/Agrégat!$B$4)*SQRT(D9))
A10: 2026-06-07 | B10: synopsis | C10: Banlieue de Montréal | D10: 300 | E10: 22 | F10: 26.8 | G10: 9.8 | H10: 34.1 | I10: 6.1 | J10: 1.2 | K10: =A10&"|"&B10 | L10: =IF(AND(C10="PROVINCE",B10<>"leger-cumul"),1,0) | M10: =DATEDIF(DATE(LEFT(A10,4),MID(A10,6,2),RIGHT(A10,2)),DATE(LEFT(Agrégat!$B$2,4),MID(Agrégat!$B$2,6,2),RIGHT(Agrégat!$B$2,2)),"d")*-1 | N10: =IFERROR(E10-SUMIFS(E$4:E$58,$K$4:$K$58,$K10,$C$4:$C$58,"PROVINCE"),0) | O10: =IFERROR(F10-SUMIFS(F$4:F$58,$K$4:$K$58,$K10,$C$4:$C$58,"PROVINCE"),0) | P10: =IFERROR(G10-SUMIFS(G$4:G$58,$K$4:$K$58,$K10,$C$4:$C$58,"PROVINCE"),0) | Q10: =IFERROR(H10-SUMIFS(H$4:H$58,$K$4:$K$58,$K10,$C$4:$C$58,"PROVINCE"),0) | R10: =IFERROR(I10-SUMIFS(I$4:I$58,$K$4:$K$58,$K10,$C$4:$C$58,"PROVINCE"),0) | S10: =IFERROR(J10-SUMIFS(J$4:J$58,$K$4:$K$58,$K10,$C$4:$C$58,"PROVINCE"),0) | T10: =IF(C10="PROVINCE",0,0.5^(-M10/Agrégat!$B$4)*SQRT(D10))
A11: 2026-06-07 | B11: synopsis | C11: Québec RMR | D11: 300 | E11: 28.9 | F11: 12.2 | G11: 7.8 | H11: 23.3 | I11: 26.7 | J11: 1.1 | K11: =A11&"|"&B11 | L11: =IF(AND(C11="PROVINCE",B11<>"leger-cumul"),1,0) | M11: =DATEDIF(DATE(LEFT(A11,4),MID(A11,6,2),RIGHT(A11,2)),DATE(LEFT(Agrégat!$B$2,4),MID(Agrégat!$B$2,6,2),RIGHT(Agrégat!$B$2,2)),"d")*-1 | N11: =IFERROR(E11-SUMIFS(E$4:E$58,$K$4:$K$58,$K11,$C$4:$C$58,"PROVINCE"),0) | O11: =IFERROR(F11-SUMIFS(F$4:F$58,$K$4:$K$58,$K11,$C$4:$C$58,"PROVINCE"),0) | P11: =IFERROR(G11-SUMIFS(G$4:G$58,$K$4:$K$58,$K11,$C$4:$C$58,"PROVINCE"),0) | Q11: =IFERROR(H11-SUMIFS(H$4:H$58,$K$4:$K$58,$K11,$C$4:$C$58,"PROVINCE"),0) | R11: =IFERROR(I11-SUMIFS(I$4:I$58,$K$4:$K$58,$K11,$C$4:$C$58,"PROVINCE"),0) | S11: =IFERROR(J11-SUMIFS(J$4:J$58,$K$4:$K$58,$K11,$C$4:$C$58,"PROVINCE"),0) | T11: =IF(C11="PROVINCE",0,0.5^(-M11/Agrégat!$B$4)*SQRT(D11))
A12: 2026-06-07 | B12: synopsis | C12: Reste du Québec | D12: 300 | E12: 19.8 | F12: 16 | G12: 12.3 | H12: 39.5 | I12: 11.1 | J12: 1.2 | K12: =A12&"|"&B12 | L12: =IF(AND(C12="PROVINCE",B12<>"leger-cumul"),1,0) | M12: =DATEDIF(DATE(LEFT(A12,4),MID(A12,6,2),RIGHT(A12,2)),DATE(LEFT(Agrégat!$B$2,4),MID(Agrégat!$B$2,6,2),RIGHT(Agrégat!$B$2,2)),"d")*-1 | N12: =IFERROR(E12-SUMIFS(E$4:E$58,$K$4:$K$58,$K12,$C$4:$C$58,"PROVINCE"),0) | O12: =IFERROR(F12-SUMIFS(F$4:F$58,$K$4:$K$58,$K12,$C$4:$C$58,"PROVINCE"),0) | P12: =IFERROR(G12-SUMIFS(G$4:G$58,$K$4:$K$58,$K12,$C$4:$C$58,"PROVINCE"),0) | Q12: =IFERROR(H12-SUMIFS(H$4:H$58,$K$4:$K$58,$K12,$C$4:$C$58,"PROVINCE"),0) | R12: =IFERROR(I12-SUMIFS(I$4:I$58,$K$4:$K$58,$K12,$C$4:$C$58,"PROVINCE"),0) | S12: =IFERROR(J12-SUMIFS(J$4:J$58,$K$4:$K$58,$K12,$C$4:$C$58,"PROVINCE"),0) | T12: =IF(C12="PROVINCE",0,0.5^(-M12/Agrégat!$B$4)*SQRT(D12))
A13: 2026-06-11 | B13: pallas | C13: PROVINCE | D13: 300 | E13: 19.8 | F13: 25.6 | G13: 11.5 | H13: 27.3 | I13: 14.6 | J13: 1.2 | K13: =A13&"|"&B13 | L13: =IF(AND(C13="PROVINCE",B13<>"leger-cumul"),1,0) | M13: =DATEDIF(DATE(LEFT(A13,4),MID(A13,6,2),RIGHT(A13,2)),DATE(LEFT(Agrégat!$B$2,4),MID(Agrégat!$B$2,6,2),RIGHT(Agrégat!$B$2,2)),"d")*-1 | N13: =IFERROR(E13-SUMIFS(E$4:E$58,$K$4:$K$58,$K13,$C$4:$C$58,"PROVINCE"),0) | O13: =IFERROR(F13-SUMIFS(F$4:F$58,$K$4:$K$58,$K13,$C$4:$C$58,"PROVINCE"),0) | P13: =IFERROR(G13-SUMIFS(G$4:G$58,$K$4:$K$58,$K13,$C$4:$C$58,"PROVINCE"),0) | Q13: =IFERROR(H13-SUMIFS(H$4:H$58,$K$4:$K$58,$K13,$C$4:$C$58,"PROVINCE"),0) | R13: =IFERROR(I13-SUMIFS(I$4:I$58,$K$4:$K$58,$K13,$C$4:$C$58,"PROVINCE"),0) | S13: =IFERROR(J13-SUMIFS(J$4:J$58,$K$4:$K$58,$K13,$C$4:$C$58,"PROVINCE"),0) | T13: =IF(C13="PROVINCE",0,0.5^(-M13/Agrégat!$B$4)*SQRT(D13))
A14: 2026-06-11 | B14: pallas | C14: Montréal RMR | D14: 300 | E14: 17.5 | F14: 33.4 | G14: 14 | H14: 24.3 | I14: 10.1 | J14: 0.7 | K14: =A14&"|"&B14 | L14: =IF(AND(C14="PROVINCE",B14<>"leger-cumul"),1,0) | M14: =DATEDIF(DATE(LEFT(A14,4),MID(A14,6,2),RIGHT(A14,2)),DATE(LEFT(Agrégat!$B$2,4),MID(Agrégat!$B$2,6,2),RIGHT(Agrégat!$B$2,2)),"d")*-1 | N14: =IFERROR(E14-SUMIFS(E$4:E$58,$K$4:$K$58,$K14,$C$4:$C$58,"PROVINCE"),0) | O14: =IFERROR(F14-SUMIFS(F$4:F$58,$K$4:$K$58,$K14,$C$4:$C$58,"PROVINCE"),0) | P14: =IFERROR(G14-SUMIFS(G$4:G$58,$K$4:$K$58,$K14,$C$4:$C$58,"PROVINCE"),0) | Q14: =IFERROR(H14-SUMIFS(H$4:H$58,$K$4:$K$58,$K14,$C$4:$C$58,"PROVINCE"),0) | R14: =IFERROR(I14-SUMIFS(I$4:I$58,$K$4:$K$58,$K14,$C$4:$C$58,"PROVINCE"),0) | S14: =IFERROR(J14-SUMIFS(J$4:J$58,$K$4:$K$58,$K14,$C$4:$C$58,"PROVINCE"),0) | T14: =IF(C14="PROVINCE",0,0.5^(-M14/Agrégat!$B$4)*SQRT(D14))
A15: 2026-06-11 | B15: pallas | C15: Île de Montréal | D15: 300 | E15: 11.2 | F15: 38.6 | G15: 20.9 | H15: 21.4 | I15: 6.9 | J15: 1.1 | K15: =A15&"|"&B15 | L15: =IF(AND(C15="PROVINCE",B15<>"leger-cumul"),1,0) | M15: =DATEDIF(DATE(LEFT(A15,4),MID(A15,6,2),RIGHT(A15,2)),DATE(LEFT(Agrégat!$B$2,4),MID(Agrégat!$B$2,6,2),RIGHT(Agrégat!$B$2,2)),"d")*-1 | N15: =IFERROR(E15-SUMIFS(E$4:E$58,$K$4:$K$58,$K15,$C$4:$C$58,"PROVINCE"),0) | O15: =IFERROR(F15-SUMIFS(F$4:F$58,$K$4:$K$58,$K15,$C$4:$C$58,"PROVINCE"),0) | P15: =IFERROR(G15-SUMIFS(G$4:G$58,$K$4:$K$58,$K15,$C$4:$C$58,"PROVINCE"),0) | Q15: =IFERROR(H15-SUMIFS(H$4:H$58,$K$4:$K$58,$K15,$C$4:$C$58,"PROVINCE"),0) | R15: =IFERROR(I15-SUMIFS(I$4:I$58,$K$4:$K$58,$K15,$C$4:$C$58,"PROVINCE"),0) | S15: =IFERROR(J15-SUMIFS(J$4:J$58,$K$4:$K$58,$K15,$C$4:$C$58,"PROVINCE"),0) | T15: =IF(C15="PROVINCE",0,0.5^(-M15/Agrégat!$B$4)*SQRT(D15))
... A58: 2026-08-29 | B58: pallas | C58: Reste du Québec | D58: 300 | E58: 24 | F58: 17.5 | G58: 12.1 | H58: 28.9 | I58: 17.3 | J58: 0.2 | K58: =A58&"|"&B58 | L58: =IF(AND(C58="PROVINCE",B58<>"leger-cumul"),1,0) | M58: =DATEDIF(DATE(LEFT(A58,4),MID(A58,6,2),RIGHT(A58,2)),DATE(LEFT(Agrégat!$B$2,4),MID(Agrégat!$B$2,6,2),RIGHT(Agrégat!$B$2,2)),"d")*-1 | N58: =IFERROR(E58-SUMIFS(E$4:E$58,$K$4:$K$58,$K58,$C$4:$C$58,"PROVINCE"),0) | O58: =IFERROR(F58-SUMIFS(F$4:F$58,$K$4:$K$58,$K58,$C$4:$C$58,"PROVINCE"),0) | P58: =IFERROR(G58-SUMIFS(G$4:G$58,$K$4:$K$58,$K58,$C$4:$C$58,"PROVINCE"),0) | Q58: =IFERROR(H58-SUMIFS(H$4:H$58,$K$4:$K$58,$K58,$C$4:$C$58,"PROVINCE"),0) | R58: =IFERROR(I58-SUMIFS(I$4:I$58,$K$4:$K$58,$K58,$C$4:$C$58,"PROVINCE"),0) | S58: =IFERROR(J58-SUMIFS(J$4:J$58,$K$4:$K$58,$K58,$C$4:$C$58,"PROVINCE"),0) | T58: =IF(C58="PROVINCE",0,0.5^(-M58/Agrégat!$B$4)*SQRT(D58))

Sheet Agrégat
A1: AGRÉGAT — niveau national (ajustement local linéaire) + décalages régionaux
A2: Date d'estimation | B2: 2026-08-31
A3: Fenêtre nationale (jours) | B3: 25
A4: Demi-vie décalages (jours) | B4: 21
A5: Autre (%) — hypothèse | B5: 1
A7: 1. NIVEAU NATIONAL — régression linéaire pondérée (poids = exp(-½(t/fenêtre)²)·√n), valeur à t=0
B8: CAQ | C8: PLQ | D8: QS | E8: PQ | F8: PCQ | G8: Autre
A9: Σw | B9: =SUMPRODUCT(EXP(-0.5*((Sondages!$M$4:$M$58)/$B$3)^2)*SQRT(Sondages!$D$4:$D$58)*Sondages!$L$4:$L$58) | C9: =SUMPRODUCT(EXP(-0.5*((Sondages!$M$4:$M$58)/$B$3)^2)*SQRT(Sondages!$D$4:$D$58)*Sondages!$L$4:$L$58) | D9: =SUMPRODUCT(EXP(-0.5*((Sondages!$M$4:$M$58)/$B$3)^2)*SQRT(Sondages!$D$4:$D$58)*Sondages!$L$4:$L$58) | E9: =SUMPRODUCT(EXP(-0.5*((Sondages!$M$4:$M$58)/$B$3)^2)*SQRT(Sondages!$D$4:$D$58)*Sondages!$L$4:$L$58) | F9: =SUMPRODUCT(EXP(-0.5*((Sondages!$M$4:$M$58)/$B$3)^2)*SQRT(Sondages!$D$4:$D$58)*Sondages!$L$4:$L$58)
A10: Σwt | B10: =SUMPRODUCT(EXP(-0.5*((Sondages!$M$4:$M$58)/$B$3)^2)*SQRT(Sondages!$D$4:$D$58)*Sondages!$L$4:$L$58,Sondages!$M$4:$M$58) | C10: =SUMPRODUCT(EXP(-0.5*((Sondages!$M$4:$M$58)/$B$3)^2)*SQRT(Sondages!$D$4:$D$58)*Sondages!$L$4:$L$58,Sondages!$M$4:$M$58) | D10: =SUMPRODUCT(EXP(-0.5*((Sondages!$M$4:$M$58)/$B$3)^2)*SQRT(Sondages!$D$4:$D$58)*Sondages!$L$4:$L$58,Sondages!$M$4:$M$58) | E10: =SUMPRODUCT(EXP(-0.5*((Sondages!$M$4:$M$58)/$B$3)^2)*SQRT(Sondages!$D$4:$D$58)*Sondages!$L$4:$L$58,Sondages!$M$4:$M$58) | F10: =SUMPRODUCT(EXP(-0.5*((Sondages!$M$4:$M$58)/$B$3)^2)*SQRT(Sondages!$D$4:$D$58)*Sondages!$L$4:$L$58,Sondages!$M$4:$M$58)
A11: Σwt² | B11: =SUMPRODUCT(EXP(-0.5*((Sondages!$M$4:$M$58)/$B$3)^2)*SQRT(Sondages!$D$4:$D$58)*Sondages!$L$4:$L$58,Sondages!$M$4:$M$58,Sondages!$M$4:$M$58) | C11: =SUMPRODUCT(EXP(-0.5*((Sondages!$M$4:$M$58)/$B$3)^2)*SQRT(Sondages!$D$4:$D$58)*Sondages!$L$4:$L$58,Sondages!$M$4:$M$58,Sondages!$M$4:$M$58) | D11: =SUMPRODUCT(EXP(-0.5*((Sondages!$M$4:$M$58)/$B$3)^2)*SQRT(Sondages!$D$4:$D$58)*Sondages!$L$4:$L$58,Sondages!$M$4:$M$58,Sondages!$M$4:$M$58) | E11: =SUMPRODUCT(EXP(-0.5*((Sondages!$M$4:$M$58)/$B$3)^2)*SQRT(Sondages!$D$4:$D$58)*Sondages!$L$4:$L$58,Sondages!$M$4:$M$58,Sondages!$M$4:$M$58) | F11: =SUMPRODUCT(EXP(-0.5*((Sondages!$M$4:$M$58)/$B$3)^2)*SQRT(Sondages!$D$4:$D$58)*Sondages!$L$4:$L$58,Sondages!$M$4:$M$58,Sondages!$M$4:$M$58)
A12: Σwy | B12: =SUMPRODUCT(EXP(-0.5*((Sondages!$M$4:$M$58)/$B$3)^2)*SQRT(Sondages!$D$4:$D$58)*Sondages!$L$4:$L$58,Sondages!$E$4:$E$58) | C12: =SUMPRODUCT(EXP(-0.5*((Sondages!$M$4:$M$58)/$B$3)^2)*SQRT(Sondages!$D$4:$D$58)*Sondages!$L$4:$L$58,Sondages!$F$4:$F$58) | D12: =SUMPRODUCT(EXP(-0.5*((Sondages!$M$4:$M$58)/$B$3)^2)*SQRT(Sondages!$D$4:$D$58)*Sondages!$L$4:$L$58,Sondages!$G$4:$G$58) | E12: =SUMPRODUCT(EXP(-0.5*((Sondages!$M$4:$M$58)/$B$3)^2)*SQRT(Sondages!$D$4:$D$58)*Sondages!$L$4:$L$58,Sondages!$H$4:$H$58) | F12: =SUMPRODUCT(EXP(-0.5*((Sondages!$M$4:$M$58)/$B$3)^2)*SQRT(Sondages!$D$4:$D$58)*Sondages!$L$4:$L$58,Sondages!$I$4:$I$58)
A13: Σwty | B13: =SUMPRODUCT(EXP(-0.5*((Sondages!$M$4:$M$58)/$B$3)^2)*SQRT(Sondages!$D$4:$D$58)*Sondages!$L$4:$L$58,Sondages!$M$4:$M$58,Sondages!$E$4:$E$58) | C13: =SUMPRODUCT(EXP(-0.5*((Sondages!$M$4:$M$58)/$B$3)^2)*SQRT(Sondages!$D$4:$D$58)*Sondages!$L$4:$L$58,Sondages!$M$4:$M$58,Sondages!$F$4:$F$58) | D13: =SUMPRODUCT(EXP(-0.5*((Sondages!$M$4:$M$58)/$B$3)^2)*SQRT(Sondages!$D$4:$D$58)*Sondages!$L$4:$L$58,Sondages!$M$4:$M$58,Sondages!$G$4:$G$58) | E13: =SUMPRODUCT(EXP(-0.5*((Sondages!$M$4:$M$58)/$B$3)^2)*SQRT(Sondages!$D$4:$D$58)*Sondages!$L$4:$L$58,Sondages!$M$4:$M$58,Sondages!$H$4:$H$58) | F13: =SUMPRODUCT(EXP(-0.5*((Sondages!$M$4:$M$58)/$B$3)^2)*SQRT(Sondages!$D$4:$D$58)*Sondages!$L$4:$L$58,Sondages!$M$4:$M$58,Sondages!$I$4:$I$58)
A14: pente b | B14: =(B9*B13-B10*B12)/(B9*B11-B10^2) | C14: =(C9*C13-C10*C12)/(C9*C11-C10^2) | D14: =(D9*D13-D10*D12)/(D9*D11-D10^2) | E14: =(E9*E13-E10*E12)/(E9*E11-E10^2) | F14: =(F9*F13-F10*F12)/(F9*F11-F10^2)
A15: niveau a | B15: =(B12-B14*B10)/B9 | C15: =(C12-C14*C10)/C9 | D15: =(D12-D14*D10)/D9 | E15: =(E12-E14*E10)/E9 | F15: =(F12-F14*F10)/F9
A16: Pente (pp / 30 j) | B16: =B14*30 | C16: =C14*30 | D16: =D14*30 | E16: =E14*30 | F16: =F14*30
A17: Niveau national (%) | B17: =B15 | C17: =C15 | D17: =D15 | E17: =E15 | F17: =F15 | G17: =B5
A19: 2. DÉCALAGES RÉGIONAUX — moyenne pondérée (récence × √n) des écarts région − province
B20: CAQ | C20: PLQ | D20: QS | E20: PQ | F20: PCQ | G20: Autre
A21: Montréal RMR | B21: =IFERROR(SUMPRODUCT((Sondages!$C$4:$C$58=$A21)*Sondages!$T$4:$T$58*Sondages!$N$4:$N$58)/SUMPRODUCT((Sondages!$C$4:$C$58=$A21)*Sondages!$T$4:$T$58),0) | C21: =IFERROR(SUMPRODUCT((Sondages!$C$4:$C$58=$A21)*Sondages!$T$4:$T$58*Sondages!$O$4:$O$58)/SUMPRODUCT((Sondages!$C$4:$C$58=$A21)*Sondages!$T$4:$T$58),0) | D21: =IFERROR(SUMPRODUCT((Sondages!$C$4:$C$58=$A21)*Sondages!$T$4:$T$58*Sondages!$P$4:$P$58)/SUMPRODUCT((Sondages!$C$4:$C$58=$A21)*Sondages!$T$4:$T$58),0) | E21: =IFERROR(SUMPRODUCT((Sondages!$C$4:$C$58=$A21)*Sondages!$T$4:$T$58*Sondages!$Q$4:$Q$58)/SUMPRODUCT((Sondages!$C$4:$C$58=$A21)*Sondages!$T$4:$T$58),0) | F21: =IFERROR(SUMPRODUCT((Sondages!$C$4:$C$58=$A21)*Sondages!$T$4:$T$58*Sondages!$R$4:$R$58)/SUMPRODUCT((Sondages!$C$4:$C$58=$A21)*Sondages!$T$4:$T$58),0) | G21: =IFERROR(SUMPRODUCT((Sondages!$C$4:$C$58=$A21)*Sondages!$T$4:$T$58*Sondages!$S$4:$S$58)/SUMPRODUCT((Sondages!$C$4:$C$58=$A21)*Sondages!$T$4:$T$58),0)
A22: Île de Montréal | B22: =IFERROR(SUMPRODUCT((Sondages!$C$4:$C$58=$A22)*Sondages!$T$4:$T$58*Sondages!$N$4:$N$58)/SUMPRODUCT((Sondages!$C$4:$C$58=$A22)*Sondages!$T$4:$T$58),0) | C22: =IFERROR(SUMPRODUCT((Sondages!$C$4:$C$58=$A22)*Sondages!$T$4:$T$58*Sondages!$O$4:$O$58)/SUMPRODUCT((Sondages!$C$4:$C$58=$A22)*Sondages!$T$4:$T$58),0) | D22: =IFERROR(SUMPRODUCT((Sondages!$C$4:$C$58=$A22)*Sondages!$T$4:$T$58*Sondages!$P$4:$P$58)/SUMPRODUCT((Sondages!$C$4:$C$58=$A22)*Sondages!$T$4:$T$58),0) | E22: =IFERROR(SUMPRODUCT((Sondages!$C$4:$C$58=$A22)*Sondages!$T$4:$T$58*Sondages!$Q$4:$Q$58)/SUMPRODUCT((Sondages!$C$4:$C$58=$A22)*Sondages!$T$4:$T$58),0) | F22: =IFERROR(SUMPRODUCT((Sondages!$C$4:$C$58=$A22)*Sondages!$T$4:$T$58*Sondages!$R$4:$R$58)/SUMPRODUCT((Sondages!$C$4:$C$58=$A22)*Sondages!$T$4:$T$58),0) | G22: =IFERROR(SUMPRODUCT((Sondages!$C$4:$C$58=$A22)*Sondages!$T$4:$T$58*Sondages!$S$4:$S$58)/SUMPRODUCT((Sondages!$C$4:$C$58=$A22)*Sondages!$T$4:$T$58),0)
A23: Banlieue de Montréal | B23: =IFERROR(SUMPRODUCT((Sondages!$C$4:$C$58=$A23)*Sondages!$T$4:$T$58*Sondages!$N$4:$N$58)/SUMPRODUCT((Sondages!$C$4:$C$58=$A23)*Sondages!$T$4:$T$58),0) | C23: =IFERROR(SUMPRODUCT((Sondages!$C$4:$C$58=$A23)*Sondages!$T$4:$T$58*Sondages!$O$4:$O$58)/SUMPRODUCT((Sondages!$C$4:$C$58=$A23)*Sondages!$T$4:$T$58),0) | D23: =IFERROR(SUMPRODUCT((Sondages!$C$4:$C$58=$A23)*Sondages!$T$4:$T$58*Sondages!$P$4:$P$58)/SUMPRODUCT((Sondages!$C$4:$C$58=$A23)*Sondages!$T$4:$T$58),0) | E23: =IFERROR(SUMPRODUCT((Sondages!$C$4:$C$58=$A23)*Sondages!$T$4:$T$58*Sondages!$Q$4:$Q$58)/SUMPRODUCT((Sondages!$C$4:$C$58=$A23)*Sondages!$T$4:$T$58),0) | F23: =IFERROR(SUMPRODUCT((Sondages!$C$4:$C$58=$A23)*Sondages!$T$4:$T$58*Sondages!$R$4:$R$58)/SUMPRODUCT((Sondages!$C$4:$C$58=$A23)*Sondages!$T$4:$T$58),0) | G23: =IFERROR(SUMPRODUCT((Sondages!$C$4:$C$58=$A23)*Sondages!$T$4:$T$58*Sondages!$S$4:$S$58)/SUMPRODUCT((Sondages!$C$4:$C$58=$A23)*Sondages!$T$4:$T$58),0)
A24: Québec RMR | B24: =IFERROR(SUMPRODUCT((Sondages!$C$4:$C$58=$A24)*Sondages!$T$4:$T$58*Sondages!$N$4:$N$58)/SUMPRODUCT((Sondages!$C$4:$C$58=$A24)*Sondages!$T$4:$T$58),0) | C24: =IFERROR(SUMPRODUCT((Sondages!$C$4:$C$58=$A24)*Sondages!$T$4:$T$58*Sondages!$O$4:$O$58)/SUMPRODUCT((Sondages!$C$4:$C$58=$A24)*Sondages!$T$4:$T$58),0) | D24: =IFERROR(SUMPRODUCT((Sondages!$C$4:$C$58=$A24)*Sondages!$T$4:$T$58*Sondages!$P$4:$P$58)/SUMPRODUCT((Sondages!$C$4:$C$58=$A24)*Sondages!$T$4:$T$58),0) | E24: =IFERROR(SUMPRODUCT((Sondages!$C$4:$C$58=$A24)*Sondages!$T$4:$T$58*Sondages!$Q$4:$Q$58)/SUMPRODUCT((Sondages!$C$4:$C$58=$A24)*Sondages!$T$4:$T$58),0) | F24: =IFERROR(SUMPRODUCT((Sondages!$C$4:$C$58=$A24)*Sondages!$T$4:$T$58*Sondages!$R$4:$R$58)/SUMPRODUCT((Sondages!$C$4:$C$58=$A24)*Sondages!$T$4:$T$58),0) | G24: =IFERROR(SUMPRODUCT((Sondages!$C$4:$C$58=$A24)*Sondages!$T$4:$T$58*Sondages!$S$4:$S$58)/SUMPRODUCT((Sondages!$C$4:$C$58=$A24)*Sondages!$T$4:$T$58),0)
A25: Reste du Québec | B25: =IFERROR(SUMPRODUCT((Sondages!$C$4:$C$58=$A25)*Sondages!$T$4:$T$58*Sondages!$N$4:$N$58)/SUMPRODUCT((Sondages!$C$4:$C$58=$A25)*Sondages!$T$4:$T$58),0) | C25: =IFERROR(SUMPRODUCT((Sondages!$C$4:$C$58=$A25)*Sondages!$T$4:$T$58*Sondages!$O$4:$O$58)/SUMPRODUCT((Sondages!$C$4:$C$58=$A25)*Sondages!$T$4:$T$58),0) | D25: =IFERROR(SUMPRODUCT((Sondages!$C$4:$C$58=$A25)*Sondages!$T$4:$T$58*Sondages!$P$4:$P$58)/SUMPRODUCT((Sondages!$C$4:$C$58=$A25)*Sondages!$T$4:$T$58),0) | E25: =IFERROR(SUMPRODUCT((Sondages!$C$4:$C$58=$A25)*Sondages!$T$4:$T$58*Sondages!$Q$4:$Q$58)/SUMPRODUCT((Sondages!$C$4:$C$58=$A25)*Sondages!$T$4:$T$58),0) | F25: =IFERROR(SUMPRODUCT((Sondages!$C$4:$C$58=$A25)*Sondages!$T$4:$T$58*Sondages!$R$4:$R$58)/SUMPRODUCT((Sondages!$C$4:$C$58=$A25)*Sondages!$T$4:$T$58),0) | G25: =IFERROR(SUMPRODUCT((Sondages!$C$4:$C$58=$A25)*Sondages!$T$4:$T$58*Sondages!$S$4:$S$58)/SUMPRODUCT((Sondages!$C$4:$C$58=$A25)*Sondages!$T$4:$T$58),0)
A27: 3. ESTIMATION RÉGIONALE = niveau national + décalage, plancher 0,2, renormalisée à 100
B28: CAQ | C28: PLQ | D28: QS | E28: PQ | F28: PCQ | G28: Autre | H28: Somme
A29: Montréal RMR | B29: =MAX(B$17+B21,0.2)/$H29*100 | C29: =MAX(C$17+C21,0.2)/$H29*100 | D29: =MAX(D$17+D21,0.2)/$H29*100 | E29: =MAX(E$17+E21,0.2)/$H29*100 | F29: =MAX(F$17+F21,0.2)/$H29*100 | G29: =MAX($B$5+G21,0.2)/$H29*100 | H29: =MAX(B$17+B21,0.2)+MAX(C$17+C21,0.2)+MAX(D$17+D21,0.2)+MAX(E$17+E21,0.2)+MAX(F$17+F21,0.2)+MAX($B$5+G21,0.2)
A30: Île de Montréal | B30: =MAX(B$17+B22,0.2)/$H30*100 | C30: =MAX(C$17+C22,0.2)/$H30*100 | D30: =MAX(D$17+D22,0.2)/$H30*100 | E30: =MAX(E$17+E22,0.2)/$H30*100 | F30: =MAX(F$17+F22,0.2)/$H30*100 | G30: =MAX($B$5+G22,0.2)/$H30*100 | H30: =MAX(B$17+B22,0.2)+MAX(C$17+C22,0.2)+MAX(D$17+D22,0.2)+MAX(E$17+E22,0.2)+MAX(F$17+F22,0.2)+MAX($B$5+G22,0.2)
A31: Banlieue de Montréal | B31: =MAX(B$17+B23,0.2)/$H31*100 | C31: =MAX(C$17+C23,0.2)/$H31*100 | D31: =MAX(D$17+D23,0.2)/$H31*100 | E31: =MAX(E$17+E23,0.2)/$H31*100 | F31: =MAX(F$17+F23,0.2)/$H31*100 | G31: =MAX($B$5+G23,0.2)/$H31*100 | H31: =MAX(B$17+B23,0.2)+MAX(C$17+C23,0.2)+MAX(D$17+D23,0.2)+MAX(E$17+E23,0.2)+MAX(F$17+F23,0.2)+MAX($B$5+G23,0.2)
A32: Québec RMR | B32: =MAX(B$17+B24,0.2)/$H32*100 | C32: =MAX(C$17+C24,0.2)/$H32*100 | D32: =MAX(D$17+D24,0.2)/$H32*100 | E32: =MAX(E$17+E24,0.2)/$H32*100 | F32: =MAX(F$17+F24,0.2)/$H32*100 | G32: =MAX($B$5+G24,0.2)/$H32*100 | H32: =MAX(B$17+B24,0.2)+MAX(C$17+C24,0.2)+MAX(D$17+D24,0.2)+MAX(E$17+E24,0.2)+MAX(F$17+F24,0.2)+MAX($B$5+G24,0.2)
A33: Reste du Québec | B33: =MAX(B$17+B25,0.2)/$H33*100 | C33: =MAX(C$17+C25,0.2)/$H33*100 | D33: =MAX(D$17+D25,0.2)/$H33*100 | E33: =MAX(E$17+E25,0.2)/$H33*100 | F33: =MAX(F$17+F25,0.2)/$H33*100 | G33: =MAX($B$5+G25,0.2)/$H33*100 | H33: =MAX(B$17+B25,0.2)+MAX(C$17+C25,0.2)+MAX(D$17+D25,0.2)+MAX(E$17+E25,0.2)+MAX(F$17+F25,0.2)+MAX($B$5+G25,0.2)

Sheet Modèle
A1: Circonscription | B1: Région | C1: Vainqueur réf. | D1: CAQ réf. | E1: PLQ réf. | F1: QS réf. | G1: PQ réf. | H1: PCQ réf. | I1: Autre réf. | J1: Total | K1: % CAQ | L1: % PLQ | M1: % QS | N1: % PQ | O1: % PCQ | P1: % Autre | Q1: A-CAQ | R1: A-PLQ | S1: A-QS | T1: A-PQ | U1: A-PCQ | V1: A-Autre | W1: B-CAQ | X1: B-PLQ | Y1: B-QS | Z1: B-PQ | AA1: B-PCQ | AB1: B-Autre | AC1: C-CAQ | AD1: C-PLQ | AE1: C-QS | AF1: C-PQ | AG1: C-PCQ | AH1: C-Autre | AI1: D-CAQ | AJ1: D-PLQ | AK1: D-QS | AL1: D-PQ | AM1: D-PCQ | AN1: D-Autre | AO1: E-CAQ | AP1: E-PLQ | AQ1: E-QS | AR1: E-PQ | AS1: E-PCQ | AT1: E-Autre | AU1: Vainq. A | AV1: Vainq. B | AW1: Vainq. C | AX1: Vainq. D | AY1: Vainq. E | AZ1: Marge réf. | BA1: Bascule | BB1: Résidu CAQ | BC1: Résidu PLQ | BD1: Résidu QS | BE1: Résidu PQ
A2: Abitibi-Est | B2: Reste du Québec | C2: =INDEX({"CAQ","PLQ","QS","PQ","PCQ","Autre"},MATCH(MAX(D2:I2),D2:I2,0)) | D2: 9762 | E2: 3044 | F2: 2838 | G2: 2565 | H2: 2486 | I2: 0 | J2: =SUM(D2:I2) | K2: =IFERROR(D2/$J2,0) | L2: =IFERROR(E2/$J2,0) | M2: =IFERROR(F2/$J2,0) | N2: =IFERROR(G2/$J2,0) | O2: =IFERROR(H2/$J2,0) | P2: =IFERROR(I2/$J2,0) | Q2: =D2*INDEX(Régions!$T$2:$T$6,MATCH($B2,Régions!$A$2:$A$6,0)) | R2: =E2*INDEX(Régions!$U$2:$U$6,MATCH($B2,Régions!$A$2:$A$6,0)) | S2: =F2*INDEX(Régions!$V$2:$V$6,MATCH($B2,Régions!$A$2:$A$6,0)) | T2: =G2*INDEX(Régions!$W$2:$W$6,MATCH($B2,Régions!$A$2:$A$6,0)) | U2: =H2*INDEX(Régions!$X$2:$X$6,MATCH($B2,Régions!$A$2:$A$6,0)) | V2: =I2*INDEX(Régions!$Y$2:$Y$6,MATCH($B2,Régions!$A$2:$A$6,0)) | W2: =Q2+(BB2/100)*$J2*Régions!$O$2 | X2: =R2+(BC2/100)*$J2*Régions!$O$2 | Y2: =S2+(BD2/100)*$J2*Régions!$O$2 | Z2: =T2+(BE2/100)*$J2*Régions!$O$2 | AA2: =U2 | AB2: =V2 | AC2: =D2*INDEX(Régions!$Z$2:$Z$6,MATCH($B2,Régions!$A$2:$A$6,0)) | AD2: =E2*INDEX(Régions!$AA$2:$AA$6,MATCH($B2,Régions!$A$2:$A$6,0)) | AE2: =F2*INDEX(Régions!$AB$2:$AB$6,MATCH($B2,Régions!$A$2:$A$6,0)) | AF2: =G2*INDEX(Régions!$AC$2:$AC$6,MATCH($B2,Régions!$A$2:$A$6,0)) | AG2: =H2*INDEX(Régions!$AD$2:$AD$6,MATCH($B2,Régions!$A$2:$A$6,0)) | AH2: =I2*INDEX(Régions!$AE$2:$AE$6,MATCH($B2,Régions!$A$2:$A$6,0)) | AI2: =D2*INDEX(Régions!$AF$2:$AF$6,MATCH($B2,Régions!$A$2:$A$6,0)) | AJ2: =E2*INDEX(Régions!$AG$2:$AG$6,MATCH($B2,Régions!$A$2:$A$6,0)) | AK2: =F2*INDEX(Régions!$AH$2:$AH$6,MATCH($B2,Régions!$A$2:$A$6,0)) | AL2: =G2*INDEX(Régions!$AI$2:$AI$6,MATCH($B2,Régions!$A$2:$A$6,0)) | AM2: =H2*INDEX(Régions!$AJ$2:$AJ$6,MATCH($B2,Régions!$A$2:$A$6,0)) | AN2: =I2*INDEX(Régions!$AK$2:$AK$6,MATCH($B2,Régions!$A$2:$A$6,0)) | AO2: =Régions!$Q$2*Q2/SUM($Q2:$V2)*100+(1-Régions!$Q$2)*MAX(K2*100+(INDEX(Régions!$AL$2:$AL$6,MATCH($B2,Régions!$A$2:$A$6,0))),0) | AP2: =Régions!$Q$2*R2/SUM($Q2:$V2)*100+(1-Régions!$Q$2)*MAX(L2*100+(INDEX(Régions!$AM$2:$AM$6,MATCH($B2,Régions!$A$2:$A$6,0))),0) | AQ2: =Régions!$Q$2*S2/SUM($Q2:$V2)*100+(1-Régions!$Q$2)*MAX(M2*100+(INDEX(Régions!$AN$2:$AN$6,MATCH($B2,Régions!$A$2:$A$6,0))),0) | AR2: =Régions!$Q$2*T2/SUM($Q2:$V2)*100+(1-Régions!$Q$2)*MAX(N2*100+(INDEX(Régions!$AO$2:$AO$6,MATCH($B2,Régions!$A$2:$A$6,0))),0) | AS2: =Régions!$Q$2*U2/SUM($Q2:$V2)*100+(1-Régions!$Q$2)*MAX(O2*100+(INDEX(Régions!$AP$2:$AP$6,MATCH($B2,Régions!$A$2:$A$6,0))),0) | AT2: =Régions!$Q$2*V2/SUM($Q2:$V2)*100+(1-Régions!$Q$2)*MAX(P2*100+(INDEX(Régions!$AQ$2:$AQ$6,MATCH($B2,Régions!$A$2:$A$6,0))),0) | AU2: =INDEX({"CAQ","PLQ","QS","PQ","PCQ","Autre"},MATCH(MAX(Q2:V2),Q2:V2,0)) | AV2: =INDEX({"CAQ","PLQ","QS","PQ","PCQ","Autre"},MATCH(MAX(W2:AB2),W2:AB2,0)) | AW2: =INDEX({"CAQ","PLQ","QS","PQ","PCQ","Autre"},MATCH(MAX(AC2:AH2),AC2:AH2,0)) | AX2: =INDEX({"CAQ","PLQ","QS","PQ","PCQ","Autre"},MATCH(MAX(AI2:AN2),AI2:AN2,0)) | AY2: =INDEX({"CAQ","PLQ","QS","PQ","PCQ","Autre"},MATCH(MAX(AO2:AT2),AO2:AT2,0)) | AZ2: =(MAX(K2:P2)-LARGE(K2:P2,2))*100 | BA2: =IF(AZ2<5,"Oui","Non") | BB2: -2.952 | BC2: 9.065 | BD2: -0.764 | BE2: -2.926
A3: Abitibi-Ouest | B3: Reste du Québec | C3: =INDEX({"CAQ","PLQ","QS","PQ","PCQ","Autre"},MATCH(MAX(D3:I3),D3:I3,0)) | D3: 10399 | E3: 1153 | F3: 3623 | G3: 4619 | H3: 2293 | I3: 159 | J3: =SUM(D3:I3) | K3: =IFERROR(D3/$J3,0) | L3: =IFERROR(E3/$J3,0) | M3: =IFERROR(F3/$J3,0) | N3: =IFERROR(G3/$J3,0) | O3: =IFERROR(H3/$J3,0) | P3: =IFERROR(I3/$J3,0) | Q3: =D3*INDEX(Régions!$T$2:$T$6,MATCH($B3,Régions!$A$2:$A$6,0)) | R3: =E3*INDEX(Régions!$U$2:$U$6,MATCH($B3,Régions!$A$2:$A$6,0)) | S3: =F3*INDEX(Régions!$V$2:$V$6,MATCH($B3,Régions!$A$2:$A$6,0)) | T3: =G3*INDEX(Régions!$W$2:$W$6,MATCH($B3,Régions!$A$2:$A$6,0)) | U3: =H3*INDEX(Régions!$X$2:$X$6,MATCH($B3,Régions!$A$2:$A$6,0)) | V3: =I3*INDEX(Régions!$Y$2:$Y$6,MATCH($B3,Régions!$A$2:$A$6,0)) | W3: =Q3+(BB3/100)*$J3*Régions!$O$2 | X3: =R3+(BC3/100)*$J3*Régions!$O$2 | Y3: =S3+(BD3/100)*$J3*Régions!$O$2 | Z3: =T3+(BE3/100)*$J3*Régions!$O$2 | AA3: =U3 | AB3: =V3 | AC3: =D3*INDEX(Régions!$Z$2:$Z$6,MATCH($B3,Régions!$A$2:$A$6,0)) | AD3: =E3*INDEX(Régions!$AA$2:$AA$6,MATCH($B3,Régions!$A$2:$A$6,0)) | AE3: =F3*INDEX(Régions!$AB$2:$AB$6,MATCH($B3,Régions!$A$2:$A$6,0)) | AF3: =G3*INDEX(Régions!$AC$2:$AC$6,MATCH($B3,Régions!$A$2:$A$6,0)) | AG3: =H3*INDEX(Régions!$AD$2:$AD$6,MATCH($B3,Régions!$A$2:$A$6,0)) | AH3: =I3*INDEX(Régions!$AE$2:$AE$6,MATCH($B3,Régions!$A$2:$A$6,0)) | AI3: =D3*INDEX(Régions!$AF$2:$AF$6,MATCH($B3,Régions!$A$2:$A$6,0)) | AJ3: =E3*INDEX(Régions!$AG$2:$AG$6,MATCH($B3,Régions!$A$2:$A$6,0)) | AK3: =F3*INDEX(Régions!$AH$2:$AH$6,MATCH($B3,Régions!$A$2:$A$6,0)) | AL3: =G3*INDEX(Régions!$AI$2:$AI$6,MATCH($B3,Régions!$A$2:$A$6,0)) | AM3: =H3*INDEX(Régions!$AJ$2:$AJ$6,MATCH($B3,Régions!$A$2:$A$6,0)) | AN3: =I3*INDEX(Régions!$AK$2:$AK$6,MATCH($B3,Régions!$A$2:$A$6,0)) | AO3: =Régions!$Q$2*Q3/SUM($Q3:$V3)*100+(1-Régions!$Q$2)*MAX(K3*100+(INDEX(Régions!$AL$2:$AL$6,MATCH($B3,Régions!$A$2:$A$6,0))),0) | AP3: =Régions!$Q$2*R3/SUM($Q3:$V3)*100+(1-Régions!$Q$2)*MAX(L3*100+(INDEX(Régions!$AM$2:$AM$6,MATCH($B3,Régions!$A$2:$A$6,0))),0) | AQ3: =Régions!$Q$2*S3/SUM($Q3:$V3)*100+(1-Régions!$Q$2)*MAX(M3*100+(INDEX(Régions!$AN$2:$AN$6,MATCH($B3,Régions!$A$2:$A$6,0))),0) | AR3: =Régions!$Q$2*T3/SUM($Q3:$V3)*100+(1-Régions!$Q$2)*MAX(N3*100+(INDEX(Régions!$AO$2:$AO$6,MATCH($B3,Régions!$A$2:$A$6,0))),0) | AS3: =Régions!$Q$2*U3/SUM($Q3:$V3)*100+(1-Régions!$Q$2)*MAX(O3*100+(INDEX(Régions!$AP$2:$AP$6,MATCH($B3,Régions!$A$2:$A$6,0))),0) | AT3: =Régions!$Q$2*V3/SUM($Q3:$V3)*100+(1-Régions!$Q$2)*MAX(P3*100+(INDEX(Régions!$AQ$2:$AQ$6,MATCH($B3,Régions!$A$2:$A$6,0))),0) | AU3: =INDEX({"CAQ","PLQ","QS","PQ","PCQ","Autre"},MATCH(MAX(Q3:V3),Q3:V3,0)) | AV3: =INDEX({"CAQ","PLQ","QS","PQ","PCQ","Autre"},MATCH(MAX(W3:AB3),W3:AB3,0)) | AW3: =INDEX({"CAQ","PLQ","QS","PQ","PCQ","Autre"},MATCH(MAX(AC3:AH3),AC3:AH3,0)) | AX3: =INDEX({"CAQ","PLQ","QS","PQ","PCQ","Autre"},MATCH(MAX(AI3:AN3),AI3:AN3,0)) | AY3: =INDEX({"CAQ","PLQ","QS","PQ","PCQ","Autre"},MATCH(MAX(AO3:AT3),AO3:AT3,0)) | AZ3: =(MAX(K3:P3)-LARGE(K3:P3,2))*100 | BA3: =IF(AZ3<5,"Oui","Non") | BB3: 5.222 | BC3: 6.979 | BD3: 0.875 | BE3: -8.33
A4: Acadie | B4: Île de Montréal | C4: =INDEX({"CAQ","PLQ","QS","PQ","PCQ","Autre"},MATCH(MAX(D4:I4),D4:I4,0)) | D4: 4446 | E4: 10981 | F4: 4468 | G4: 2565 | H4: 2955 | I4: 569 | J4: =SUM(D4:I4) | K4: =IFERROR(D4/$J4,0) | L4: =IFERROR(E4/$J4,0) | M4: =IFERROR(F4/$J4,0) | N4: =IFERROR(G4/$J4,0) | O4: =IFERROR(H4/$J4,0) | P4: =IFERROR(I4/$J4,0) | Q4: =D4*INDEX(Régions!$T$2:$T$6,MATCH($B4,Régions!$A$2:$A$6,0)) | R4: =E4*INDEX(Régions!$U$2:$U$6,MATCH($B4,Régions!$A$2:$A$6,0)) | S4: =F4*INDEX(Régions!$V$2:$V$6,MATCH($B4,Régions!$A$2:$A$6,0)) | T4: =G4*INDEX(Régions!$W$2:$W$6,MATCH($B4,Régions!$A$2:$A$6,0)) | U4: =H4*INDEX(Régions!$X$2:$X$6,MATCH($B4,Régions!$A$2:$A$6,0)) | V4: =I4*INDEX(Régions!$Y$2:$Y$6,MATCH($B4,Régions!$A$2:$A$6,0)) | W4: =Q4+(BB4/100)*$J4*Régions!$O$2 | X4: =R4+(BC4/100)*$J4*Régions!$O$2 | Y4: =S4+(BD4/100)*$J4*Régions!$O$2 | Z4: =T4+(BE4/100)*$J4*Régions!$O$2 | AA4: =U4 | AB4: =V4 | AC4: =D4*INDEX(Régions!$Z$2:$Z$6,MATCH($B4,Régions!$A$2:$A$6,0)) | AD4: =E4*INDEX(Régions!$AA$2:$AA$6,MATCH($B4,Régions!$A$2:$A$6,0)) | AE4: =F4*INDEX(Régions!$AB$2:$AB$6,MATCH($B4,Régions!$A$2:$A$6,0)) | AF4: =G4*INDEX(Régions!$AC$2:$AC$6,MATCH($B4,Régions!$A$2:$A$6,0)) | AG4: =H4*INDEX(Régions!$AD$2:$AD$6,MATCH($B4,Régions!$A$2:$A$6,0)) | AH4: =I4*INDEX(Régions!$AE$2:$AE$6,MATCH($B4,Régions!$A$2:$A$6,0)) | AI4: =D4*INDEX(Régions!$AF$2:$AF$6,MATCH($B4,Régions!$A$2:$A$6,0)) | AJ4: =E4*INDEX(Régions!$AG$2:$AG$6,MATCH($B4,Régions!$A$2:$A$6,0)) | AK4: =F4*INDEX(Régions!$AH$2:$AH$6,MATCH($B4,Régions!$A$2:$A$6,0)) | AL4: =G4*INDEX(Régions!$AI$2:$AI$6,MATCH($B4,Régions!$A$2:$A$6,0)) | AM4: =H4*INDEX(Régions!$AJ$2:$AJ$6,MATCH($B4,Régions!$A$2:$A$6,0)) | AN4: =I4*INDEX(Régions!$AK$2:$AK$6,MATCH($B4,Régions!$A$2:$A$6,0)) | AO4: =Régions!$Q$2*Q4/SUM($Q4:$V4)*100+(1-Régions!$Q$2)*MAX(K4*100+(INDEX(Régions!$AL$2:$AL$6,MATCH($B4,Régions!$A$2:$A$6,0))),0) | AP4: =Régions!$Q$2*R4/SUM($Q4:$V4)*100+(1-Régions!$Q$2)*MAX(L4*100+(INDEX(Régions!$AM$2:$AM$6,MATCH($B4,Régions!$A$2:$A$6,0))),0) | AQ4: =Régions!$Q$2*S4/SUM($Q4:$V4)*100+(1-Régions!$Q$2)*MAX(M4*100+(INDEX(Régions!$AN$2:$AN$6,MATCH($B4,Régions!$A$2:$A$6,0))),0) | AR4: =Régions!$Q$2*T4/SUM($Q4:$V4)*100+(1-Régions!$Q$2)*MAX(N4*100+(INDEX(Régions!$AO$2:$AO$6,MATCH($B4,Régions!$A$2:$A$6,0))),0) | AS4: =Régions!$Q$2*U4/SUM($Q4:$V4)*100+(1-Régions!$Q$2)*MAX(O4*100+(INDEX(Régions!$AP$2:$AP$6,MATCH($B4,Régions!$A$2:$A$6,0))),0) | AT4: =Régions!$Q$2*V4/SUM($Q4:$V4)*100+(1-Régions!$Q$2)*MAX(P4*100+(INDEX(Régions!$AQ$2:$AQ$6,MATCH($B4,Régions!$A$2:$A$6,0))),0) | AU4: =INDEX({"CAQ","PLQ","QS","PQ","PCQ","Autre"},MATCH(MAX(Q4:V4),Q4:V4,0)) | AV4: =INDEX({"CAQ","PLQ","QS","PQ","PCQ","Autre"},MATCH(MAX(W4:AB4),W4:AB4,0)) | AW4: =INDEX({"CAQ","PLQ","QS","PQ","PCQ","Autre"},MATCH(MAX(AC4:AH4),AC4:AH4,0)) | AX4: =INDEX({"CAQ","PLQ","QS","PQ","PCQ","Autre"},MATCH(MAX(AI4:AN4),AI4:AN4,0)) | AY4: =INDEX({"CAQ","PLQ","QS","PQ","PCQ","Autre"},MATCH(MAX(AO4:AT4),AO4:AT4,0)) | AZ4: =(MAX(K4:P4)-LARGE(K4:P4,2))*100 | BA4: =IF(AZ4<5,"Oui","Non") | BB4: -1.354 | BC4: -2.737 | BD4: 2.672 | BE4: 1.972
A5: Anjou-Louis-Riel | B5: Île de Montréal | C5: =INDEX({"CAQ","PLQ","QS","PQ","PCQ","Autre"},MATCH(MAX(D5:I5),D5:I5,0)) | D5: 9376 | E5: 8045 | F5: 3893 | G5: 2910 | H5: 1887 | I5: 252 | J5: =SUM(D5:I5) | K5: =IFERROR(D5/$J5,0) | L5: =IFERROR(E5/$J5,0) | M5: =IFERROR(F5/$J5,0) | N5: =IFERROR(G5/$J5,0) | O5: =IFERROR(H5/$J5,0) | P5: =IFERROR(I5/$J5,0) | Q5: =D5*INDEX(Régions!$T$2:$T$6,MATCH($B5,Régions!$A$2:$A$6,0)) | R5: =E5*INDEX(Régions!$U$2:$U$6,MATCH($B5,Régions!$A$2:$A$6,0)) | S5: =F5*INDEX(Régions!$V$2:$V$6,MATCH($B5,Régions!$A$2:$A$6,0)) | T5: =G5*INDEX(Régions!$W$2:$W$6,MATCH($B5,Régions!$A$2:$A$6,0)) | U5: =H5*INDEX(Régions!$X$2:$X$6,MATCH($B5,Régions!$A$2:$A$6,0)) | V5: =I5*INDEX(Régions!$Y$2:$Y$6,MATCH($B5,Régions!$A$2:$A$6,0)) | W5: =Q5+(BB5/100)*$J5*Régions!$O$2 | X5: =R5+(BC5/100)*$J5*Régions!$O$2 | Y5: =S5+(BD5/100)*$J5*Régions!$O$2 | Z5: =T5+(BE5/100)*$J5*Régions!$O$2 | AA5: =U5 | AB5: =V5 | AC5: =D5*INDEX(Régions!$Z$2:$Z$6,MATCH($B5,Régions!$A$2:$A$6,0)) | AD5: =E5*INDEX(Régions!$AA$2:$AA$6,MATCH($B5,Régions!$A$2:$A$6,0)) | AE5: =F5*INDEX(Régions!$AB$2:$AB$6,MATCH($B5,Régions!$A$2:$A$6,0)) | AF5: =G5*INDEX(Régions!$AC$2:$AC$6,MATCH($B5,Régions!$A$2:$A$6,0)) | AG5: =H5*INDEX(Régions!$AD$2:$AD$6,MATCH($B5,Régions!$A$2:$A$6,0)) | AH5: =I5*INDEX(Régions!$AE$2:$AE$6,MATCH($B5,Régions!$A$2:$A$6,0)) | AI5: =D5*INDEX(Régions!$AF$2:$AF$6,MATCH($B5,Régions!$A$2:$A$6,0)) | AJ5: =E5*INDEX(Régions!$AG$2:$AG$6,MATCH($B5,Régions!$A$2:$A$6,0)) | AK5: =F5*INDEX(Régions!$AH$2:$AH$6,MATCH($B5,Régions!$A$2:$A$6,0)) | AL5: =G5*INDEX(Régions!$AI$2:$AI$6,MATCH($B5,Régions!$A$2:$A$6,0)) | AM5: =H5*INDEX(Régions!$AJ$2:$AJ$6,MATCH($B5,Régions!$A$2:$A$6,0)) | AN5: =I5*INDEX(Régions!$AK$2:$AK$6,MATCH($B5,Régions!$A$2:$A$6,0)) | AO5: =Régions!$Q$2*Q5/SUM($Q5:$V5)*100+(1-Régions!$Q$2)*MAX(K5*100+(INDEX(Régions!$AL$2:$AL$6,MATCH($B5,Régions!$A$2:$A$6,0))),0) | AP5: =Régions!$Q$2*R5/SUM($Q5:$V5)*100+(1-Régions!$Q$2)*MAX(L5*100+(INDEX(Régions!$AM$2:$AM$6,MATCH($B5,Régions!$A$2:$A$6,0))),0) | AQ5: =Régions!$Q$2*S5/SUM($Q5:$V5)*100+(1-Régions!$Q$2)*MAX(M5*100+(INDEX(Régions!$AN$2:$AN$6,MATCH($B5,Régions!$A$2:$A$6,0))),0) | AR5: =Régions!$Q$2*T5/SUM($Q5:$V5)*100+(1-Régions!$Q$2)*MAX(N5*100+(INDEX(Régions!$AO$2:$AO$6,MATCH($B5,Régions!$A$2:$A$6,0))),0) | AS5: =Régions!$Q$2*U5/SUM($Q5:$V5)*100+(1-Régions!$Q$2)*MAX(O5*100+(INDEX(Régions!$AP$2:$AP$6,MATCH($B5,Régions!$A$2:$A$6,0))),0) | AT5: =Régions!$Q$2*V5/SUM($Q5:$V5)*100+(1-Régions!$Q$2)*MAX(P5*100+(INDEX(Régions!$AQ$2:$AQ$6,MATCH($B5,Régions!$A$2:$A$6,0))),0) | AU5: =INDEX({"CAQ","PLQ","QS","PQ","PCQ","Autre"},MATCH(MAX(Q5:V5),Q5:V5,0)) | AV5: =INDEX({"CAQ","PLQ","QS","PQ","PCQ","Autre"},MATCH(MAX(W5:AB5),W5:AB5,0)) | AW5: =INDEX({"CAQ","PLQ","QS","PQ","PCQ","Autre"},MATCH(MAX(AC5:AH5),AC5:AH5,0)) | AX5: =INDEX({"CAQ","PLQ","QS","PQ","PCQ","Autre"},MATCH(MAX(AI5:AN5),AI5:AN5,0)) | AY5: =INDEX({"CAQ","PLQ","QS","PQ","PCQ","Autre"},MATCH(MAX(AO5:AT5),AO5:AT5,0)) | AZ5: =(MAX(K5:P5)-LARGE(K5:P5,2))*100 | BA5: =IF(AZ5<5,"Oui","Non") | BB5: 4.703 | BC5: 0.254 | BD5: -0.537 | BE5: -2.554
A6: Argenteuil | B6: Reste du Québec | C6: =INDEX({"CAQ","PLQ","QS","PQ","PCQ","Autre"},MATCH(MAX(D6:I6),D6:I6,0)) | D6: 11414.3 | E6: 2535.1 | F6: 2753.4 | G6: 4090 | H6: 4004.6 | I6: 407.8 | J6: =SUM(D6:I6) | K6: =IFERROR(D6/$J6,0) | L6: =IFERROR(E6/$J6,0) | M6: =IFERROR(F6/$J6,0) | N6: =IFERROR(G6/$J6,0) | O6: =IFERROR(H6/$J6,0) | P6: =IFERROR(I6/$J6,0) | Q6: =D6*INDEX(Régions!$T$2:$T$6,MATCH($B6,Régions!$A$2:$A$6,0)) | R6: =E6*INDEX(Régions!$U$2:$U$6,MATCH($B6,Régions!$A$2:$A$6,0)) | S6: =F6*INDEX(Régions!$V$2:$V$6,MATCH($B6,Régions!$A$2:$A$6,0)) | T6: =G6*INDEX(Régions!$W$2:$W$6,MATCH($B6,Régions!$A$2:$A$6,0)) | U6: =H6*INDEX(Régions!$X$2:$X$6,MATCH($B6,Régions!$A$2:$A$6,0)) | V6: =I6*INDEX(Régions!$Y$2:$Y$6,MATCH($B6,Régions!$A$2:$A$6,0)) | W6: =Q6+(BB6/100)*$J6*Régions!$O$2 | X6: =R6+(BC6/100)*$J6*Régions!$O$2 | Y6: =S6+(BD6/100)*$J6*Régions!$O$2 | Z6: =T6+(BE6/100)*$J6*Régions!$O$2 | AA6: =U6 | AB6: =V6 | AC6: =D6*INDEX(Régions!$Z$2:$Z$6,MATCH($B6,Régions!$A$2:$A$6,0)) | AD6: =E6*INDEX(Régions!$AA$2:$AA$6,MATCH($B6,Régions!$A$2:$A$6,0)) | AE6: =F6*INDEX(Régions!$AB$2:$AB$6,MATCH($B6,Régions!$A$2:$A$6,0)) | AF6: =G6*INDEX(Régions!$AC$2:$AC$6,MATCH($B6,Régions!$A$2:$A$6,0)) | AG6: =H6*INDEX(Régions!$AD$2:$AD$6,MATCH($B6,Régions!$A$2:$A$6,0)) | AH6: =I6*INDEX(Régions!$AE$2:$AE$6,MATCH($B6,Régions!$A$2:$A$6,0)) | AI6: =D6*INDEX(Régions!$AF$2:$AF$6,MATCH($B6,Régions!$A$2:$A$6,0)) | AJ6: =E6*INDEX(Régions!$AG$2:$AG$6,MATCH($B6,Régions!$A$2:$A$6,0)) | AK6: =F6*INDEX(Régions!$AH$2:$AH$6,MATCH($B6,Régions!$A$2:$A$6,0)) | AL6: =G6*INDEX(Régions!$AI$2:$AI$6,MATCH($B6,Régions!$A$2:$A$6,0)) | AM6: =H6*INDEX(Régions!$AJ$2:$AJ$6,MATCH($B6,Régions!$A$2:$A$6,0)) | AN6: =I6*INDEX(Régions!$AK$2:$AK$6,MATCH($B6,Régions!$A$2:$A$6,0)) | AO6: =Régions!$Q$2*Q6/SUM($Q6:$V6)*100+(1-Régions!$Q$2)*MAX(K6*100+(INDEX(Régions!$AL$2:$AL$6,MATCH($B6,Régions!$A$2:$A$6,0))),0) | AP6: =Régions!$Q$2*R6/SUM($Q6:$V6)*100+(1-Régions!$Q$2)*MAX(L6*100+(INDEX(Régions!$AM$2:$AM$6,MATCH($B6,Régions!$A$2:$A$6,0))),0) | AQ6: =Régions!$Q$2*S6/SUM($Q6:$V6)*100+(1-Régions!$Q$2)*MAX(M6*100+(INDEX(Régions!$AN$2:$AN$6,MATCH($B6,Régions!$A$2:$A$6,0))),0) | AR6: =Régions!$Q$2*T6/SUM($Q6:$V6)*100+(1-Régions!$Q$2)*MAX(N6*100+(INDEX(Régions!$AO$2:$AO$6,MATCH($B6,Régions!$A$2:$A$6,0))),0) | AS6: =Régions!$Q$2*U6/SUM($Q6:$V6)*100+(1-Régions!$Q$2)*MAX(O6*100+(INDEX(Régions!$AP$2:$AP$6,MATCH($B6,Régions!$A$2:$A$6,0))),0) | AT6: =Régions!$Q$2*V6/SUM($Q6:$V6)*100+(1-Régions!$Q$2)*MAX(P6*100+(INDEX(Régions!$AQ$2:$AQ$6,MATCH($B6,Régions!$A$2:$A$6,0))),0) | AU6: =INDEX({"CAQ","PLQ","QS","PQ","PCQ","Autre"},MATCH(MAX(Q6:V6),Q6:V6,0)) | AV6: =INDEX({"CAQ","PLQ","QS","PQ","PCQ","Autre"},MATCH(MAX(W6:AB6),W6:AB6,0)) | AW6: =INDEX({"CAQ","PLQ","QS","PQ","PCQ","Autre"},MATCH(MAX(AC6:AH6),AC6:AH6,0)) | AX6: =INDEX({"CAQ","PLQ","QS","PQ","PCQ","Autre"},MATCH(MAX(AI6:AN6),AI6:AN6,0)) | AY6: =INDEX({"CAQ","PLQ","QS","PQ","PCQ","Autre"},MATCH(MAX(AO6:AT6),AO6:AT6,0)) | AZ6: =(MAX(K6:P6)-LARGE(K6:P6,2))*100 | BA6: =IF(AZ6<5,"Oui","Non") | BB6: -1.563 | BC6: 6.06 | BD6: -0.168 | BE6: -0.639
A7: Arthabaska-L'Érable | B7: Reste du Québec | C7: =INDEX({"CAQ","PLQ","QS","PQ","PCQ","Autre"},MATCH(MAX(D7:I7),D7:I7,0)) | D7: 22986.3 | E7: 1669.1 | F7: 4100.1 | G7: 4460 | H7: 10951.2 | I7: 252.5 | J7: =SUM(D7:I7) | K7: =IFERROR(D7/$J7,0) | L7: =IFERROR(E7/$J7,0) | M7: =IFERROR(F7/$J7,0) | N7: =IFERROR(G7/$J7,0) | O7: =IFERROR(H7/$J7,0) | P7: =IFERROR(I7/$J7,0) | Q7: =D7*INDEX(Régions!$T$2:$T$6,MATCH($B7,Régions!$A$2:$A$6,0)) | R7: =E7*INDEX(Régions!$U$2:$U$6,MATCH($B7,Régions!$A$2:$A$6,0)) | S7: =F7*INDEX(Régions!$V$2:$V$6,MATCH($B7,Régions!$A$2:$A$6,0)) | T7: =G7*INDEX(Régions!$W$2:$W$6,MATCH($B7,Régions!$A$2:$A$6,0)) | U7: =H7*INDEX(Régions!$X$2:$X$6,MATCH($B7,Régions!$A$2:$A$6,0)) | V7: =I7*INDEX(Régions!$Y$2:$Y$6,MATCH($B7,Régions!$A$2:$A$6,0)) | W7: =Q7+(BB7/100)*$J7*Régions!$O$2 | X7: =R7+(BC7/100)*$J7*Régions!$O$2 | Y7: =S7+(BD7/100)*$J7*Régions!$O$2 | Z7: =T7+(BE7/100)*$J7*Régions!$O$2 | AA7: =U7 | AB7: =V7 | AC7: =D7*INDEX(Régions!$Z$2:$Z$6,MATCH($B7,Régions!$A$2:$A$6,0)) | AD7: =E7*INDEX(Régions!$AA$2:$AA$6,MATCH($B7,Régions!$A$2:$A$6,0)) | AE7: =F7*INDEX(Régions!$AB$2:$AB$6,MATCH($B7,Régions!$A$2:$A$6,0)) | AF7: =G7*INDEX(Régions!$AC$2:$AC$6,MATCH($B7,Régions!$A$2:$A$6,0)) | AG7: =H7*INDEX(Régions!$AD$2:$AD$6,MATCH($B7,Régions!$A$2:$A$6,0)) | AH7: =I7*INDEX(Régions!$AE$2:$AE$6,MATCH($B7,Régions!$A$2:$A$6,0)) | AI7: =D7*INDEX(Régions!$AF$2:$AF$6,MATCH($B7,Régions!$A$2:$A$6,0)) | AJ7: =E7*INDEX(Régions!$AG$2:$AG$6,MATCH($B7,Régions!$A$2:$A$6,0)) | AK7: =F7*INDEX(Régions!$AH$2:$AH$6,MATCH($B7,Régions!$A$2:$A$6,0)) | AL7: =G7*INDEX(Régions!$AI$2:$AI$6,MATCH($B7,Régions!$A$2:$A$6,0)) | AM7: =H7*INDEX(Régions!$AJ$2:$AJ$6,MATCH($B7,Régions!$A$2:$A$6,0)) | AN7: =I7*INDEX(Régions!$AK$2:$AK$6,MATCH($B7,Régions!$A$2:$A$6,0)) | AO7: =Régions!$Q$2*Q7/SUM($Q7:$V7)*100+(1-Régions!$Q$2)*MAX(K7*100+(INDEX(Régions!$AL$2:$AL$6,MATCH($B7,Régions!$A$2:$A$6,0))),0) | AP7: =Régions!$Q$2*R7/SUM($Q7:$V7)*100+(1-Régions!$Q$2)*MAX(L7*100+(INDEX(Régions!$AM$2:$AM$6,MATCH($B7,Régions!$A$2:$A$6,0))),0) | AQ7: =Régions!$Q$2*S7/SUM($Q7:$V7)*100+(1-Régions!$Q$2)*MAX(M7*100+(INDEX(Régions!$AN$2:$AN$6,MATCH($B7,Régions!$A$2:$A$6,0))),0) | AR7: =Régions!$Q$2*T7/SUM($Q7:$V7)*100+(1-Régions!$Q$2)*MAX(N7*100+(INDEX(Régions!$AO$2:$AO$6,MATCH($B7,Régions!$A$2:$A$6,0))),0) | AS7: =Régions!$Q$2*U7/SUM($Q7:$V7)*100+(1-Régions!$Q$2)*MAX(O7*100+(INDEX(Régions!$AP$2:$AP$6,MATCH($B7,Régions!$A$2:$A$6,0))),0) | AT7: =Régions!$Q$2*V7/SUM($Q7:$V7)*100+(1-Régions!$Q$2)*MAX(P7*100+(INDEX(Régions!$AQ$2:$AQ$6,MATCH($B7,Régions!$A$2:$A$6,0))),0) | AU7: =INDEX({"CAQ","PLQ","QS","PQ","PCQ","Autre"},MATCH(MAX(Q7:V7),Q7:V7,0)) | AV7: =INDEX({"CAQ","PLQ","QS","PQ","PCQ","Autre"},MATCH(MAX(W7:AB7),W7:AB7,0)) | AW7: =INDEX({"CAQ","PLQ","QS","PQ","PCQ","Autre"},MATCH(MAX(AC7:AH7),AC7:AH7,0)) | AX7: =INDEX({"CAQ","PLQ","QS","PQ","PCQ","Autre"},MATCH(MAX(AI7:AN7),AI7:AN7,0)) | AY7: =INDEX({"CAQ","PLQ","QS","PQ","PCQ","Autre"},MATCH(MAX(AO7:AT7),AO7:AT7,0)) | AZ7: =(MAX(K7:P7)-LARGE(K7:P7,2))*100 | BA7: =IF(AZ7<5,"Oui","Non") | BB7: -17.462 | BC7: 5.505 | BD7: -2.178 | BE7: 4.79
A8: Beauce-Nord | B8: Reste du Québec | C8: =INDEX({"CAQ","PLQ","QS","PQ","PCQ","Autre"},MATCH(MAX(D8:I8),D8:I8,0)) | D8: 14590 | E8: 951 | F8: 1522 | G8: 1994 | H8: 14388 | I8: 146 | J8: =SUM(D8:I8) | K8: =IFERROR(D8/$J8,0) | L8: =IFERROR(E8/$J8,0) | M8: =IFERROR(F8/$J8,0) | N8: =IFERROR(G8/$J8,0) | O8: =IFERROR(H8/$J8,0) | P8: =IFERROR(I8/$J8,0) | Q8: =D8*INDEX(Régions!$T$2:$T$6,MATCH($B8,Régions!$A$2:$A$6,0)) | R8: =E8*INDEX(Régions!$U$2:$U$6,MATCH($B8,Régions!$A$2:$A$6,0)) | S8: =F8*INDEX(Régions!$V$2:$V$6,MATCH($B8,Régions!$A$2:$A$6,0)) | T8: =G8*INDEX(Régions!$W$2:$W$6,MATCH($B8,Régions!$A$2:$A$6,0)) | U8: =H8*INDEX(Régions!$X$2:$X$6,MATCH($B8,Régions!$A$2:$A$6,0)) | V8: =I8*INDEX(Régions!$Y$2:$Y$6,MATCH($B8,Régions!$A$2:$A$6,0)) | W8: =Q8+(BB8/100)*$J8*Régions!$O$2 | X8: =R8+(BC8/100)*$J8*Régions!$O$2 | Y8: =S8+(BD8/100)*$J8*Régions!$O$2 | Z8: =T8+(BE8/100)*$J8*Régions!$O$2 | AA8: =U8 | AB8: =V8 | AC8: =D8*INDEX(Régions!$Z$2:$Z$6,MATCH($B8,Régions!$A$2:$A$6,0)) | AD8: =E8*INDEX(Régions!$AA$2:$AA$6,MATCH($B8,Régions!$A$2:$A$6,0)) | AE8: =F8*INDEX(Régions!$AB$2:$AB$6,MATCH($B8,Régions!$A$2:$A$6,0)) | AF8: =G8*INDEX(Régions!$AC$2:$AC$6,MATCH($B8,Régions!$A$2:$A$6,0)) | AG8: =H8*INDEX(Régions!$AD$2:$AD$6,MATCH($B8,Régions!$A$2:$A$6,0)) | AH8: =I8*INDEX(Régions!$AE$2:$AE$6,MATCH($B8,Régions!$A$2:$A$6,0)) | AI8: =D8*INDEX(Régions!$AF$2:$AF$6,MATCH($B8,Régions!$A$2:$A$6,0)) | AJ8: =E8*INDEX(Régions!$AG$2:$AG$6,MATCH($B8,Régions!$A$2:$A$6,0)) | AK8: =F8*INDEX(Régions!$AH$2:$AH$6,MATCH($B8,Régions!$A$2:$A$6,0)) | AL8: =G8*INDEX(Régions!$AI$2:$AI$6,MATCH($B8,Régions!$A$2:$A$6,0)) | AM8: =H8*INDEX(Régions!$AJ$2:$AJ$6,MATCH($B8,Régions!$A$2:$A$6,0)) | AN8: =I8*INDEX(Régions!$AK$2:$AK$6,MATCH($B8,Régions!$A$2:$A$6,0)) | AO8: =Régions!$Q$2*Q8/SUM($Q8:$V8)*100+(1-Régions!$Q$2)*MAX(K8*100+(INDEX(Régions!$AL$2:$AL$6,MATCH($B8,Régions!$A$2:$A$6,0))),0) | AP8: =Régions!$Q$2*R8/SUM($Q8:$V8)*100+(1-Régions!$Q$2)*MAX(L8*100+(INDEX(Régions!$AM$2:$AM$6,MATCH($B8,Régions!$A$2:$A$6,0))),0) | AQ8: =Régions!$Q$2*S8/SUM($Q8:$V8)*100+(1-Régions!$Q$2)*MAX(M8*100+(INDEX(Régions!$AN$2:$AN$6,MATCH($B8,Régions!$A$2:$A$6,0))),0) | AR8: =Régions!$Q$2*T8/SUM($Q8:$V8)*100+(1-Régions!$Q$2)*MAX(N8*100+(INDEX(Régions!$AO$2:$AO$6,MATCH($B8,Régions!$A$2:$A$6,0))),0) | AS8: =Régions!$Q$2*U8/SUM($Q8:$V8)*100+(1-Régions!$Q$2)*MAX(O8*100+(INDEX(Régions!$AP$2:$AP$6,MATCH($B8,Régions!$A$2:$A$6,0))),0) | AT8: =Régions!$Q$2*V8/SUM($Q8:$V8)*100+(1-Régions!$Q$2)*MAX(P8*100+(INDEX(Régions!$AQ$2:$AQ$6,MATCH($B8,Régions!$A$2:$A$6,0))),0) | AU8: =INDEX({"CAQ","PLQ","QS","PQ","PCQ","Autre"},MATCH(MAX(Q8:V8),Q8:V8,0)) | AV8: =INDEX({"CAQ","PLQ","QS","PQ","PCQ","Autre"},MATCH(MAX(W8:AB8),W8:AB8,0)) | AW8: =INDEX({"CAQ","PLQ","QS","PQ","PCQ","Autre"},MATCH(MAX(AC8:AH8),AC8:AH8,0)) | AX8: =INDEX({"CAQ","PLQ","QS","PQ","PCQ","Autre"},MATCH(MAX(AI8:AN8),AI8:AN8,0)) | AY8: =INDEX({"CAQ","PLQ","QS","PQ","PCQ","Autre"},MATCH(MAX(AO8:AT8),AO8:AT8,0)) | AZ8: =(MAX(K8:P8)-LARGE(K8:P8,2))*100 | BA8: =IF(AZ8<5,"Oui","Non") | BB8: -30.339 | BC8: 0.275 | BD8: -1.345 | BE8: 4.98
A9: Beauce-Sud | B9: Reste du Québec | C9: =INDEX({"CAQ","PLQ","QS","PQ","PCQ","Autre"},MATCH(MAX(D9:I9),D9:I9,0)) | D9: 16615 | E9: 1057 | F9: 1623 | G9: 1505 | H9: 16187 | I9: 306 | J9: =SUM(D9:I9) | K9: =IFERROR(D9/$J9,0) | L9: =IFERROR(E9/$J9,0) | M9: =IFERROR(F9/$J9,0) | N9: =IFERROR(G9/$J9,0) | O9: =IFERROR(H9/$J9,0) | P9: =IFERROR(I9/$J9,0) | Q9: =D9*INDEX(Régions!$T$2:$T$6,MATCH($B9,Régions!$A$2:$A$6,0)) | R9: =E9*INDEX(Régions!$U$2:$U$6,MATCH($B9,Régions!$A$2:$A$6,0)) | S9: =F9*INDEX(Régions!$V$2:$V$6,MATCH($B9,Régions!$A$2:$A$6,0)) | T9: =G9*INDEX(Régions!$W$2:$W$6,MATCH($B9,Régions!$A$2:$A$6,0)) | U9: =H9*INDEX(Régions!$X$2:$X$6,MATCH($B9,Régions!$A$2:$A$6,0)) | V9: =I9*INDEX(Régions!$Y$2:$Y$6,MATCH($B9,Régions!$A$2:$A$6,0)) | W9: =Q9+(BB9/100)*$J9*Régions!$O$2 | X9: =R9+(BC9/100)*$J9*Régions!$O$2 | Y9: =S9+(BD9/100)*$J9*Régions!$O$2 | Z9: =T9+(BE9/100)*$J9*Régions!$O$2 | AA9: =U9 | AB9: =V9 | AC9: =D9*INDEX(Régions!$Z$2:$Z$6,MATCH($B9,Régions!$A$2:$A$6,0)) | AD9: =E9*INDEX(Régions!$AA$2:$AA$6,MATCH($B9,Régions!$A$2:$A$6,0)) | AE9: =F9*INDEX(Régions!$AB$2:$AB$6,MATCH($B9,Régions!$A$2:$A$6,0)) | AF9: =G9*INDEX(Régions!$AC$2:$AC$6,MATCH($B9,Régions!$A$2:$A$6,0)) | AG9: =H9*INDEX(Régions!$AD$2:$AD$6,MATCH($B9,Régions!$A$2:$A$6,0)) | AH9: =I9*INDEX(Régions!$AE$2:$AE$6,MATCH($B9,Régions!$A$2:$A$6,0)) | AI9: =D9*INDEX(Régions!$AF$2:$AF$6,MATCH($B9,Régions!$A$2:$A$6,0)) | AJ9: =E9*INDEX(Régions!$AG$2:$AG$6,MATCH($B9,Régions!$A$2:$A$6,0)) | AK9: =F9*INDEX(Régions!$AH$2:$AH$6,MATCH($B9,Régions!$A$2:$A$6,0)) | AL9: =G9*INDEX(Régions!$AI$2:$AI$6,MATCH($B9,Régions!$A$2:$A$6,0)) | AM9: =H9*INDEX(Régions!$AJ$2:$AJ$6,MATCH($B9,Régions!$A$2:$A$6,0)) | AN9: =I9*INDEX(Régions!$AK$2:$AK$6,MATCH($B9,Régions!$A$2:$A$6,0)) | AO9: =Régions!$Q$2*Q9/SUM($Q9:$V9)*100+(1-Régions!$Q$2)*MAX(K9*100+(INDEX(Régions!$AL$2:$AL$6,MATCH($B9,Régions!$A$2:$A$6,0))),0) | AP9: =Régions!$Q$2*R9/SUM($Q9:$V9)*100+(1-Régions!$Q$2)*MAX(L9*100+(INDEX(Régions!$AM$2:$AM$6,MATCH($B9,Régions!$A$2:$A$6,0))),0) | AQ9: =Régions!$Q$2*S9/SUM($Q9:$V9)*100+(1-Régions!$Q$2)*MAX(M9*100+(INDEX(Régions!$AN$2:$AN$6,MATCH($B9,Régions!$A$2:$A$6,0))),0) | AR9: =Régions!$Q$2*T9/SUM($Q9:$V9)*100+(1-Régions!$Q$2)*MAX(N9*100+(INDEX(Régions!$AO$2:$AO$6,MATCH($B9,Régions!$A$2:$A$6,0))),0) | AS9: =Régions!$Q$2*U9/SUM($Q9:$V9)*100+(1-Régions!$Q$2)*MAX(O9*100+(INDEX(Régions!$AP$2:$AP$6,MATCH($B9,Régions!$A$2:$A$6,0))),0) | AT9: =Régions!$Q$2*V9/SUM($Q9:$V9)*100+(1-Régions!$Q$2)*MAX(P9*100+(INDEX(Régions!$AQ$2:$AQ$6,MATCH($B9,Régions!$A$2:$A$6,0))),0) | AU9: =INDEX({"CAQ","PLQ","QS","PQ","PCQ","Autre"},MATCH(MAX(Q9:V9),Q9:V9,0)) | AV9: =INDEX({"CAQ","PLQ","QS","PQ","PCQ","Autre"},MATCH(MAX(W9:AB9),W9:AB9,0)) | AW9: =INDEX({"CAQ","PLQ","QS","PQ","PCQ","Autre"},MATCH(MAX(AC9:AH9),AC9:AH9,0)) | AX9: =INDEX({"CAQ","PLQ","QS","PQ","PCQ","Autre"},MATCH(MAX(AI9:AN9),AI9:AN9,0)) | AY9: =INDEX({"CAQ","PLQ","QS","PQ","PCQ","Autre"},MATCH(MAX(AO9:AT9),AO9:AT9,0)) | AZ9: =(MAX(K9:P9)-LARGE(K9:P9,2))*100 | BA9: =IF(AZ9<5,"Oui","Non") | BB9: -25.532 | BC9: -4.889 | BD9: -0.256 | BE9: 4.087
A10: Beauharnois | B10: Banlieue de Montréal | C10: =INDEX({"CAQ","PLQ","QS","PQ","PCQ","Autre"},MATCH(MAX(D10:I10),D10:I10,0)) | D10: 19553.9 | E10: 2795.9 | F10: 4724.3 | G10: 6042.9 | H10: 3601.1 | I10: 456.7 | J10: =SUM(D10:I10) | K10: =IFERROR(D10/$J10,0) | L10: =IFERROR(E10/$J10,0) | M10: =IFERROR(F10/$J10,0) | N10: =IFERROR(G10/$J10,0) | O10: =IFERROR(H10/$J10,0) | P10: =IFERROR(I10/$J10,0) | Q10: =D10*INDEX(Régions!$T$2:$T$6,MATCH($B10,Régions!$A$2:$A$6,0)) | R10: =E10*INDEX(Régions!$U$2:$U$6,MATCH($B10,Régions!$A$2:$A$6,0)) | S10: =F10*INDEX(Régions!$V$2:$V$6,MATCH($B10,Régions!$A$2:$A$6,0)) | T10: =G10*INDEX(Régions!$W$2:$W$6,MATCH($B10,Régions!$A$2:$A$6,0)) | U10: =H10*INDEX(Régions!$X$2:$X$6,MATCH($B10,Régions!$A$2:$A$6,0)) | V10: =I10*INDEX(Régions!$Y$2:$Y$6,MATCH($B10,Régions!$A$2:$A$6,0)) | W10: =Q10+(BB10/100)*$J10*Régions!$O$2 | X10: =R10+(BC10/100)*$J10*Régions!$O$2 | Y10: =S10+(BD10/100)*$J10*Régions!$O$2 | Z10: =T10+(BE10/100)*$J10*Régions!$O$2 | AA10: =U10 | AB10: =V10 | AC10: =D10*INDEX(Régions!$Z$2:$Z$6,MATCH($B10,Régions!$A$2:$A$6,0)) | AD10: =E10*INDEX(Régions!$AA$2:$AA$6,MATCH($B10,Régions!$A$2:$A$6,0)) | AE10: =F10*INDEX(Régions!$AB$2:$AB$6,MATCH($B10,Régions!$A$2:$A$6,0)) | AF10: =G10*INDEX(Régions!$AC$2:$AC$6,MATCH($B10,Régions!$A$2:$A$6,0)) | AG10: =H10*INDEX(Régions!$AD$2:$AD$6,MATCH($B10,Régions!$A$2:$A$6,0)) | AH10: =I10*INDEX(Régions!$AE$2:$AE$6,MATCH($B10,Régions!$A$2:$A$6,0)) | AI10: =D10*INDEX(Régions!$AF$2:$AF$6,MATCH($B10,Régions!$A$2:$A$6,0)) | AJ10: =E10*INDEX(Régions!$AG$2:$AG$6,MATCH($B10,Régions!$A$2:$A$6,0)) | AK10: =F10*INDEX(Régions!$AH$2:$AH$6,MATCH($B10,Régions!$A$2:$A$6,0)) | AL10: =G10*INDEX(Régions!$AI$2:$AI$6,MATCH($B10,Régions!$A$2:$A$6,0)) | AM10: =H10*INDEX(Régions!$AJ$2:$AJ$6,MATCH($B10,Régions!$A$2:$A$6,0)) | AN10: =I10*INDEX(Régions!$AK$2:$AK$6,MATCH($B10,Régions!$A$2:$A$6,0)) | AO10: =Régions!$Q$2*Q10/SUM($Q10:$V10)*100+(1-Régions!$Q$2)*MAX(K10*100+(INDEX(Régions!$AL$2:$AL$6,MATCH($B10,Régions!$A$2:$A$6,0))),0) | AP10: =Régions!$Q$2*R10/SUM($Q10:$V10)*100+(1-Régions!$Q$2)*MAX(L10*100+(INDEX(Régions!$AM$2:$AM$6,MATCH($B10,Régions!$A$2:$A$6,0))),0) | AQ10: =Régions!$Q$2*S10/SUM($Q10:$V10)*100+(1-Régions!$Q$2)*MAX(M10*100+(INDEX(Régions!$AN$2:$AN$6,MATCH($B10,Régions!$A$2:$A$6,0))),0) | AR10: =Régions!$Q$2*T10/SUM($Q10:$V10)*100+(1-Régions!$Q$2)*MAX(N10*100+(INDEX(Régions!$AO$2:$AO$6,MATCH($B10,Régions!$A$2:$A$6,0))),0) | AS10: =Régions!$Q$2*U10/SUM($Q10:$V10)*100+(1-Régions!$Q$2)*MAX(O10*100+(INDEX(Régions!$AP$2:$AP$6,MATCH($B10,Régions!$A$2:$A$6,0))),0) | AT10: =Régions!$Q$2*V10/SUM($Q10:$V10)*100+(1-Régions!$Q$2)*MAX(P10*100+(INDEX(Régions!$AQ$2:$AQ$6,MATCH($B10,Régions!$A$2:$A$6,0))),0) | AU10: =INDEX({"CAQ","PLQ","QS","PQ","PCQ","Autre"},MATCH(MAX(Q10:V10),Q10:V10,0)) | AV10: =INDEX({"CAQ","PLQ","QS","PQ","PCQ","Autre"},MATCH(MAX(W10:AB10),W10:AB10,0)) | AW10: =INDEX({"CAQ","PLQ","QS","PQ","PCQ","Autre"},MATCH(MAX(AC10:AH10),AC10:AH10,0)) | AX10: =INDEX({"CAQ","PLQ","QS","PQ","PCQ","Autre"},MATCH(MAX(AI10:AN10),AI10:AN10,0)) | AY10: =INDEX({"CAQ","PLQ","QS","PQ","PCQ","Autre"},MATCH(MAX(AO10:AT10),AO10:AT10,0)) | AZ10: =(MAX(K10:P10)-LARGE(K10:P10,2))*100 | BA10: =IF(AZ10<5,"Oui","Non") | BB10: 3.579 | BC10: -0.558 | BD10: -1.36 | BE10: -1.198
A11: Bellechasse | B11: Reste du Québec | C11: =INDEX({"CAQ","PLQ","QS","PQ","PCQ","Autre"},MATCH(MAX(D11:I11),D11:I11,0)) | D11: 15065 | E11: 1360 | F11: 1988 | G11: 2908 | H11: 11612 | I11: 0 | J11: =SUM(D11:I11) | K11: =IFERROR(D11/$J11,0) | L11: =IFERROR(E11/$J11,0) | M11: =IFERROR(F11/$J11,0) | N11: =IFERROR(G11/$J11,0) | O11: =IFERROR(H11/$J11,0) | P11: =IFERROR(I11/$J11,0) | Q11: =D11*INDEX(Régions!$T$2:$T$6,MATCH($B11,Régions!$A$2:$A$6,0)) | R11: =E11*INDEX(Régions!$U$2:$U$6,MATCH($B11,Régions!$A$2:$A$6,0)) | S11: =F11*INDEX(Régions!$V$2:$V$6,MATCH($B11,Régions!$A$2:$A$6,0)) | T11: =G11*INDEX(Régions!$W$2:$W$6,MATCH($B11,Régions!$A$2:$A$6,0)) | U11: =H11*INDEX(Régions!$X$2:$X$6,MATCH($B11,Régions!$A$2:$A$6,0)) | V11: =I11*INDEX(Régions!$Y$2:$Y$6,MATCH($B11,Régions!$A$2:$A$6,0)) | W11: =Q11+(BB11/100)*$J11*Régions!$O$2 | X11: =R11+(BC11/100)*$J11*Régions!$O$2 | Y11: =S11+(BD11/100)*$J11*Régions!$O$2 | Z11: =T11+(BE11/100)*$J11*Régions!$O$2 | AA11: =U11 | AB11: =V11 | AC11: =D11*INDEX(Régions!$Z$2:$Z$6,MATCH($B11,Régions!$A$2:$A$6,0)) | AD11: =E11*INDEX(Régions!$AA$2:$AA$6,MATCH($B11,Régions!$A$2:$A$6,0)) | AE11: =F11*INDEX(Régions!$AB$2:$AB$6,MATCH($B11,Régions!$A$2:$A$6,0)) | AF11: =G11*INDEX(Régions!$AC$2:$AC$6,MATCH($B11,Régions!$A$2:$A$6,0)) | AG11: =H11*INDEX(Régions!$AD$2:$AD$6,MATCH($B11,Régions!$A$2:$A$6,0)) | AH11: =I11*INDEX(Régions!$AE$2:$AE$6,MATCH($B11,Régions!$A$2:$A$6,0)) | AI11: =D11*INDEX(Régions!$AF$2:$AF$6,MATCH($B11,Régions!$A$2:$A$6,0)) | AJ11: =E11*INDEX(Régions!$AG$2:$AG$6,MATCH($B11,Régions!$A$2:$A$6,0)) | AK11: =F11*INDEX(Régions!$AH$2:$AH$6,MATCH($B11,Régions!$A$2:$A$6,0)) | AL11: =G11*INDEX(Régions!$AI$2:$AI$6,MATCH($B11,Régions!$A$2:$A$6,0)) | AM11: =H11*INDEX(Régions!$AJ$2:$AJ$6,MATCH($B11,Régions!$A$2:$A$6,0)) | AN11: =I11*INDEX(Régions!$AK$2:$AK$6,MATCH($B11,Régions!$A$2:$A$6,0)) | AO11: =Régions!$Q$2*Q11/SUM($Q11:$V11)*100+(1-Régions!$Q$2)*MAX(K11*100+(INDEX(Régions!$AL$2:$AL$6,MATCH($B11,Régions!$A$2:$A$6,0))),0) | AP11: =Régions!$Q$2*R11/SUM($Q11:$V11)*100+(1-Régions!$Q$2)*MAX(L11*100+(INDEX(Régions!$AM$2:$AM$6,MATCH($B11,Régions!$A$2:$A$6,0))),0) | AQ11: =Régions!$Q$2*S11/SUM($Q11:$V11)*100+(1-Régions!$Q$2)*MAX(M11*100+(INDEX(Régions!$AN$2:$AN$6,MATCH($B11,Régions!$A$2:$A$6,0))),0) | AR11: =Régions!$Q$2*T11/SUM($Q11:$V11)*100+(1-Régions!$Q$2)*MAX(N11*100+(INDEX(Régions!$AO$2:$AO$6,MATCH($B11,Régions!$A$2:$A$6,0))),0) | AS11: =Régions!$Q$2*U11/SUM($Q11:$V11)*100+(1-Régions!$Q$2)*MAX(O11*100+(INDEX(Régions!$AP$2:$AP$6,MATCH($B11,Régions!$A$2:$A$6,0))),0) | AT11: =Régions!$Q$2*V11/SUM($Q11:$V11)*100+(1-Régions!$Q$2)*MAX(P11*100+(INDEX(Régions!$AQ$2:$AQ$6,MATCH($B11,Régions!$A$2:$A$6,0))),0) | AU11: =INDEX({"CAQ","PLQ","QS","PQ","PCQ","Autre"},MATCH(MAX(Q11:V11),Q11:V11,0)) | AV11: =INDEX({"CAQ","PLQ","QS","PQ","PCQ","Autre"},MATCH(MAX(W11:AB11),W11:AB11,0)) | AW11: =INDEX({"CAQ","PLQ","QS","PQ","PCQ","Autre"},MATCH(MAX(AC11:AH11),AC11:AH11,0)) | AX11: =INDEX({"CAQ","PLQ","QS","PQ","PCQ","Autre"},MATCH(MAX(AI11:AN11),AI11:AN11,0)) | AY11: =INDEX({"CAQ","PLQ","QS","PQ","PCQ","Autre"},MATCH(MAX(AO11:AT11),AO11:AT11,0)) | AZ11: =(MAX(K11:P11)-LARGE(K11:P11,2))*100 | BA11: =IF(AZ11<5,"Oui","Non") | BB11: -15.508 | BC11: -9.925 | BD11: -0.286 | BE11: 5.734
